

--Bull Banksia 02 Tree
	local N = gal.N

	
	return {
	yslice_prob = {
		
	},
	size = {
		y = 14,
		x = 9,
		z = 9
	},
	data = {
		N["_____"],N["_____"],N["_____"],N["_____"],N["_____"],N["_____"],N["_____"],N["_____"],N["_____"],N["_____"],N["_____"],N["_____"],N["_____"],N["_____"],N["_____"],N["_____"],N["_____"],N["_____"],N["_____"],N["_____"],N["_____"],N["_____"],N["_____"],N["_____"],N["_____"],N["_____"],N["_____"],N["_____"],N["_____"],N["_____"],N["_____"],N["_____"],N["_____"],N["_____"],N["_____"],N["_____"],N["_____"],N["_____"],N["_____"],N["_____"],N["_____"],N["_____"],N["_____"],N["_____"],N["_____"],N["_____"],N["_____"],N["_____"],N["_____"],N["_____"],N["_____"],N["_____"],N["_____"],N["_____"],N["_____"],N["_____"],N["_____"],N["_____"],N["_____"],N["_____"],N["_____"],N["_____"],N["_____"],N["_____"],N["_____"],N["_____"],N["_____"],N["_____"],N["_____"],N["_____"],N["_____"],N["_____"],N["_____"],N["_____"],N["_____"],N["_____"],
		N["L0m02"],
		N["_____"],N["_____"],N["_____"],N["_____"],N["_____"],N["_____"],N["_____"],N["_____"],N["_____"],N["_____"],N["_____"],N["_____"],N["_____"],N["_____"],N["_____"],N["_____"],N["_____"],N["_____"],N["_____"],N["_____"],N["_____"],N["_____"],N["_____"],N["_____"],N["_____"],N["_____"],N["_____"],N["_____"],N["_____"],N["_____"],N["_____"],N["_____"],N["_____"],N["_____"],N["_____"],N["_____"],N["_____"],N["_____"],N["_____"],N["_____"],N["_____"],N["_____"],N["_____"],N["_____"],N["_____"],N["_____"],N["_____"],N["_____"],N["_____"],N["_____"],N["_____"],N["_____"],N["_____"],N["_____"],N["_____"],N["_____"],N["_____"],N["_____"],N["_____"],N["_____"],N["_____"],N["_____"],N["_____"],N["_____"],N["_____"],N["_____"],N["_____"],N["_____"],N["_____"],N["_____"],N["_____"],N["_____"],N["_____"],N["_____"],N["_____"],N["_____"],N["_____"],N["_____"],N["_____"],N["_____"],N["_____"],N["_____"],N["_____"],N["_____"],N["_____"],N["_____"],N["_____"],N["_____"],N["_____"],N["_____"],N["_____"],N["_____"],N["_____"],N["_____"],N["_____"],N["_____"],N["_____"],N["_____"],N["_____"],N["_____"],N["_____"],N["_____"],N["_____"],N["_____"],N["_____"],N["_____"],
		N["L0m02"],
		N["L0m02"],
		N["L0m02"],
		N["_____"],N["_____"],N["_____"],N["_____"],N["_____"],
		N["L0m02"],
		N["L0m02"],
		N["L0m02"],
		N["L0m02"],
		N["L0m02"],
		N["_____"],N["_____"],N["_____"],N["_____"],
		N["L0m02"],
		N["L0m02"],
		N["L0m01"],
		N["L0m02"],
		N["L0m02"],
		N["_____"],N["_____"],N["_____"],N["_____"],
		N["L0m02"],
		N["L0m02"],
		N["L0m02"],
		N["L0m02"],
		N["L0m02"],
		N["_____"],N["_____"],N["_____"],N["_____"],N["_____"],
		N["L0m02"],
		N["L0m02"],
		N["L0m02"],
		N["_____"],N["_____"],N["_____"],N["_____"],N["_____"],N["_____"],N["_____"],N["_____"],N["_____"],N["_____"],N["_____"],N["_____"],N["_____"],N["_____"],N["_____"],N["_____"],N["_____"],N["_____"],N["_____"],N["_____"],N["_____"],N["_____"],N["_____"],N["_____"],N["_____"],N["_____"],N["_____"],N["_____"],N["_____"],N["_____"],N["_____"],N["_____"],N["_____"],N["_____"],N["_____"],N["_____"],N["_____"],N["_____"],N["_____"],N["_____"],N["_____"],N["_____"],N["_____"],N["_____"],N["_____"],N["_____"],N["_____"],N["_____"],N["_____"],N["_____"],N["_____"],N["_____"],N["_____"],N["_____"],N["_____"],N["_____"],N["_____"],N["_____"],N["_____"],N["_____"],N["_____"],N["_____"],N["_____"],N["_____"],N["_____"],N["_____"],N["_____"],N["_____"],N["_____"],N["_____"],N["_____"],N["_____"],N["_____"],N["_____"],N["_____"],N["_____"],N["_____"],N["_____"],N["_____"],N["_____"],N["_____"],N["_____"],N["_____"],N["_____"],N["_____"],N["_____"],
		N["L0m02"],
		N["L0m02"],
		N["L0m02"],
		N["L0m02"],
		N["L0m02"],
		N["_____"],N["_____"],N["_____"],N["_____"],
		N["L0m02"],
		N["L0m01"],
		N["L0m01"],
		N["L0m01"],
		N["L0m02"],
		N["L0m02"],
		N["_____"],N["_____"],N["_____"],
		N["L0m02"],
		N["L0m01"],
		N["L0m00"],
		N["L0m01"],
		N["L0m02"],
		N["L0m02"],
		N["_____"],N["_____"],N["_____"],
		N["L0m02"],
		N["L0m01"],
		N["L0m01"],
		N["L0m01"],
		N["L0m02"],
		N["L0m02"],
		N["_____"],N["_____"],N["_____"],
		N["L0m02"],
		N["L0m02"],
		N["L0m02"],
		N["L0m02"],
		N["L0m02"],
		N["_____"],N["_____"],N["_____"],N["_____"],N["_____"],N["_____"],N["_____"],N["_____"],N["_____"],N["_____"],N["_____"],N["_____"],N["_____"],N["_____"],N["_____"],N["_____"],N["_____"],N["_____"],N["_____"],N["_____"],N["_____"],N["_____"],N["_____"],N["_____"],N["_____"],N["_____"],N["_____"],N["_____"],N["_____"],N["_____"],N["_____"],N["_____"],N["_____"],N["_____"],N["_____"],N["_____"],N["_____"],N["_____"],N["_____"],N["_____"],N["_____"],N["_____"],N["_____"],N["_____"],N["_____"],N["_____"],N["_____"],N["_____"],N["_____"],N["_____"],N["_____"],N["_____"],N["_____"],N["_____"],N["_____"],N["_____"],N["_____"],N["_____"],N["_____"],N["_____"],N["_____"],N["_____"],N["_____"],N["_____"],N["_____"],N["_____"],N["_____"],N["_____"],N["_____"],N["_____"],N["_____"],N["_____"],N["_____"],N["_____"],N["_____"],N["_____"],N["_____"],N["_____"],
		N["L0m02"],
		N["_____"],N["_____"],N["_____"],N["_____"],N["_____"],N["_____"],
		N["L0m02"],
		N["L0m02"],
		N["L0m01"],
		N["L0m02"],
		N["L0m02"],
		N["L0m02"],
		N["_____"],N["_____"],N["_____"],
		N["L0m02"],
		N["L0m01"],
		N["L0m00"],
		N["L0m01"],
		N["L0m01"],
		N["L0m02"],
		N["_____"],N["_____"],
		N["L0m02"],
		N["L0m01"],
		N["L0m00"],
		N["T0m00"],
		N["L0m00"],
		N["L0m01"],
		N["L0m02"],
		N["_____"],N["_____"],N["_____"],
		N["L0m02"],
		N["L0m01"],
		N["L0m00"],
		N["L0m01"],
		N["L0m01"],
		N["L0m02"],
		N["_____"],N["_____"],N["_____"],
		N["L0m02"],
		N["L0m02"],
		N["L0m01"],
		N["L0m02"],
		N["L0m02"],
		N["L0m02"],
		N["_____"],N["_____"],N["_____"],N["_____"],N["_____"],
		N["L0m02"],
		N["_____"],N["_____"],N["_____"],N["_____"],N["_____"],N["_____"],N["_____"],N["_____"],N["_____"],N["_____"],N["_____"],N["_____"],N["_____"],N["_____"],N["_____"],N["_____"],N["_____"],N["_____"],N["_____"],N["_____"],N["_____"],N["_____"],N["_____"],N["_____"],N["_____"],N["_____"],N["_____"],N["_____"],N["_____"],N["_____"],N["_____"],N["_____"],N["_____"],N["_____"],N["_____"],
		N["T0m00"],
		N["_____"],N["_____"],N["_____"],N["_____"],N["_____"],N["_____"],N["_____"],N["_____"],
		N["T0m00"],
		N["_____"],N["_____"],N["_____"],N["_____"],N["_____"],N["_____"],N["_____"],N["_____"],
		N["T0m00"],
		N["_____"],N["_____"],N["_____"],N["_____"],N["_____"],N["_____"],N["_____"],N["_____"],
		N["T0m00"],
		N["_____"],N["_____"],N["_____"],N["_____"],N["_____"],N["_____"],N["_____"],N["_____"],
		N["T0m00"],
		N["L0m02"],
		N["_____"],N["_____"],N["_____"],N["_____"],N["_____"],
		N["L0m02"],
		N["L0m02"],
		N["T0m00"],
		N["L0m01"],
		N["L0m02"],
		N["L0m02"],
		N["_____"],N["_____"],N["_____"],
		N["L0m02"],
		N["L0m01"],
		N["T0m00"],
		N["L0m00"],
		N["L0m01"],
		N["L0m02"],
		N["_____"],N["_____"],
		N["L0m02"],
		N["L0m01"],
		N["L0m00"],
		N["T0m00"],
		N["T0m00"],
		N["L0m00"],
		N["L0m01"],
		N["L0m02"],
		N["_____"],N["_____"],
		N["L0m02"],
		N["L0m01"],
		N["L0m00"],
		N["L0m00"],
		N["L0m01"],
		N["L0m02"],
		N["_____"],N["_____"],N["_____"],
		N["L0m02"],
		N["L0m02"],
		N["L0m01"],
		N["L0m01"],
		N["L0m02"],
		N["L0m02"],
		N["_____"],N["_____"],N["_____"],N["_____"],N["_____"],
		N["L0m02"],
		N["L0m02"],
		N["_____"],N["_____"],N["_____"],N["_____"],N["_____"],N["_____"],N["_____"],N["_____"],N["_____"],N["_____"],N["_____"],N["_____"],N["_____"],N["_____"],N["_____"],N["_____"],N["_____"],N["_____"],N["_____"],N["_____"],N["_____"],N["_____"],N["_____"],N["_____"],N["_____"],N["_____"],N["_____"],N["_____"],N["_____"],N["_____"],N["_____"],N["_____"],N["_____"],N["_____"],N["_____"],N["_____"],N["_____"],N["_____"],N["_____"],N["_____"],N["_____"],N["_____"],N["_____"],N["_____"],N["_____"],N["_____"],N["_____"],N["_____"],N["_____"],N["_____"],N["_____"],N["_____"],N["_____"],N["_____"],N["_____"],N["_____"],N["_____"],N["_____"],N["_____"],N["_____"],N["_____"],N["_____"],N["_____"],N["_____"],N["_____"],N["_____"],N["_____"],N["_____"],N["_____"],N["_____"],N["_____"],N["_____"],N["_____"],N["_____"],N["_____"],N["_____"],N["_____"],
		N["L0m02"],
		N["L0m02"],
		N["L0m02"],
		N["L0m02"],
		N["L0m02"],
		N["L0m02"],
		N["_____"],N["_____"],N["_____"],
		N["L0m02"],
		N["L0m01"],
		N["L0m01"],
		N["L0m01"],
		N["L0m01"],
		N["L0m02"],
		N["_____"],N["_____"],N["_____"],
		N["L0m02"],
		N["L0m01"],
		N["L0m00"],
		N["L0m00"],
		N["L0m01"],
		N["L0m02"],
		N["_____"],N["_____"],N["_____"],
		N["L0m02"],
		N["L0m01"],
		N["L0m01"],
		N["L0m01"],
		N["L0m01"],
		N["L0m02"],
		N["_____"],N["_____"],N["_____"],
		N["L0m02"],
		N["L0m02"],
		N["L0m02"],
		N["L0m02"],
		N["L0m02"],
		N["L0m02"],
		N["_____"],N["_____"],N["_____"],N["_____"],N["_____"],N["_____"],N["_____"],N["_____"],N["_____"],N["_____"],N["_____"],N["_____"],N["_____"],N["_____"],N["_____"],N["_____"],N["_____"],N["_____"],N["_____"],N["_____"],N["_____"],N["_____"],N["_____"],N["_____"],N["_____"],N["_____"],N["_____"],N["_____"],N["_____"],N["_____"],N["_____"],N["_____"],N["_____"],N["_____"],N["_____"],N["_____"],N["_____"],N["_____"],N["_____"],N["_____"],N["_____"],N["_____"],N["_____"],N["_____"],N["_____"],N["_____"],N["_____"],N["_____"],N["_____"],N["_____"],N["_____"],N["_____"],N["_____"],N["_____"],N["_____"],N["_____"],N["_____"],N["_____"],N["_____"],N["_____"],N["_____"],N["_____"],N["_____"],N["_____"],N["_____"],N["_____"],N["_____"],N["_____"],N["_____"],N["_____"],N["_____"],N["_____"],N["_____"],N["_____"],N["_____"],N["_____"],N["_____"],N["_____"],N["_____"],N["_____"],N["_____"],N["_____"],N["_____"],N["_____"],N["_____"],
		N["L0m02"],
		N["L0m02"],
		N["L0m02"],
		N["L0m02"],
		N["_____"],N["_____"],N["_____"],N["_____"],
		N["L0m02"],
		N["L0m02"],
		N["L0m02"],
		N["L0m02"],
		N["L0m02"],
		N["L0m02"],
		N["_____"],N["_____"],N["_____"],
		N["L0m02"],
		N["L0m02"],
		N["L0m01"],
		N["L0m01"],
		N["L0m02"],
		N["L0m02"],
		N["_____"],N["_____"],N["_____"],
		N["L0m02"],
		N["L0m02"],
		N["L0m02"],
		N["L0m02"],
		N["L0m02"],
		N["L0m02"],
		N["_____"],N["_____"],N["_____"],N["_____"],
		N["L0m02"],
		N["L0m02"],
		N["L0m02"],
		N["L0m02"],
		N["_____"],N["_____"],N["_____"],N["_____"],N["_____"],N["_____"],N["_____"],N["_____"],N["_____"],N["_____"],N["_____"],N["_____"],N["_____"],N["_____"],N["_____"],N["_____"],N["_____"],N["_____"],N["_____"],N["_____"],N["_____"],N["_____"],N["_____"],N["_____"],N["_____"],N["_____"],N["_____"],N["_____"],N["_____"],N["_____"],N["_____"],N["_____"],N["_____"],N["_____"],N["_____"],N["_____"],N["_____"],N["_____"],N["_____"],N["_____"],N["_____"],N["_____"],N["_____"],N["_____"],N["_____"],N["_____"],N["_____"],N["_____"],N["_____"],N["_____"],N["_____"],N["_____"],N["_____"],N["_____"],N["_____"],N["_____"],N["_____"],N["_____"],N["_____"],N["_____"],N["_____"],N["_____"],N["_____"],N["_____"],N["_____"],N["_____"],N["_____"],N["_____"],N["_____"],N["_____"],N["_____"],N["_____"],N["_____"],N["_____"],N["_____"],N["_____"],N["_____"],N["_____"],N["_____"],N["_____"],N["_____"],N["_____"],N["_____"],N["_____"],N["_____"],N["_____"],N["_____"],N["_____"],N["_____"],N["_____"],N["_____"],N["_____"],N["_____"],N["_____"],N["_____"],N["_____"],N["_____"],N["_____"],N["_____"],N["_____"],N["_____"],N["_____"],N["_____"],N["_____"],N["_____"],
		N["L0m02"],
		N["L0m02"],
		N["_____"],N["_____"],N["_____"],N["_____"],N["_____"],N["_____"],N["_____"],N["_____"],N["_____"],N["_____"],N["_____"],N["_____"],N["_____"],N["_____"],N["_____"],N["_____"],N["_____"],N["_____"],N["_____"],N["_____"],N["_____"],N["_____"],N["_____"],N["_____"],N["_____"],N["_____"],N["_____"],N["_____"],N["_____"],N["_____"],N["_____"],N["_____"],N["_____"],N["_____"],N["_____"],N["_____"],N["_____"],N["_____"],N["_____"],N["_____"],N["_____"],N["_____"],N["_____"],N["_____"],N["_____"],N["_____"],N["_____"],N["_____"],N["_____"],N["_____"],N["_____"],N["_____"],N["_____"],N["_____"],N["_____"],N["_____"],N["_____"],N["_____"],N["_____"],N["_____"],N["_____"],N["_____"],N["_____"],N["_____"],N["_____"],N["_____"],N["_____"],N["_____"],N["_____"],N["_____"],N["_____"],N["_____"],N["_____"],N["_____"],N["_____"],N["_____"],N["_____"],N["_____"],N["_____"],N["_____"],N["_____"],N["_____"],N["_____"],N["_____"],N["_____"],N["_____"],N["_____"],N["_____"],N["_____"],N["_____"],N["_____"],N["_____"],N["_____"],N["_____"],N["_____"],N["_____"],N["_____"],N["_____"],N["_____"],N["_____"],N["_____"],N["_____"],N["_____"],N["_____"],N["_____"],N["_____"],N["_____"],N["_____"],N["_____"],N["_____"],N["_____"],N["_____"],N["_____"],N["_____"],N["_____"],N["_____"],N["_____"],N["_____"],N["_____"],N["_____"],N["_____"],N["_____"],N["_____"],N["_____"],N["_____"],N["_____"],N["_____"],N["_____"],N["_____"],N["_____"],N["_____"],N["_____"],N["_____"],N["_____"],N["_____"],N["_____"],N["_____"],N["_____"],N["_____"],N["_____"],N["_____"],N["_____"],N["_____"],N["_____"],N["_____"],N["_____"],N["_____"],N["_____"],N["_____"],N["_____"],N["_____"],N["_____"],N["_____"],N["_____"],N["_____"],N["_____"],N["_____"],N["_____"],N["_____"],N["_____"],N["_____"],N["_____"],N["_____"],N["_____"],N["_____"],N["_____"],N["_____"],N["_____"],N["_____"],N["_____"],N["_____"],N["_____"],N["_____"],N["_____"]
	}
}