




--Red Mangrove 01
	local N = gal.N

	N["R0m00"] = {name = "gal:tree_mangrove_root",param2 = 0,prob = 254, force_place = true}
	
	return 	{
		size = {x = 4,y = 12,z = 4},
		data = {
			N["_____"], N["_____"], N["_____"], N["_____"],
			N["_____"], N["_____"], N["_____"], N["_____"],
			N["_____"], N["_____"], N["_____"], N["_____"],
			N["_____"], N["_____"], N["_____"], N["_____"],
			N["_____"], N["_____"], N["_____"], N["_____"],
			N["_____"], N["_____"], N["_____"], N["_____"],
			N["_____"], N["_____"], N["_____"], N["_____"],
			N["_____"], N["_____"], N["_____"], N["_____"],
			N["_____"], N["L0m00"], N["L0m00"], N["L0m00"],
			N["_____"], N["_____"], N["_____"], N["_____"],
			N["_____"], N["L0m00"], N["L0m00"], N["L0m00"],
			N["_____"], N["_____"], N["_____"], N["_____"],
			
			N["R0m00"], N["R0m00"], N["_____"], N["_____"],
			N["_____"], N["_____"], N["_____"], N["_____"],
			N["_____"], N["T0m00"], N["_____"], N["_____"],
			N["_____"], N["_____"], N["_____"], N["_____"],
			N["_____"], N["_____"], N["_____"], N["_____"],
			N["_____"], N["_____"], N["_____"], N["_____"],
			N["_____"], N["_____"], N["_____"], N["_____"],
			N["_____"], N["_____"], N["_____"], N["_____"],
			N["_____"], N["L0m00"], N["T0m00"], N["L0m00"],
			N["_____"], N["_____"], N["L0m00"], N["_____"],
			N["_____"], N["L0m00"], N["T0m00"], N["L0m00"],
			N["_____"], N["_____"], N["L0m00"], N["_____"],
			
			N["R0m00"], N["R0m00"], N["_____"], N["_____"],
			N["_____"], N["_____"], N["_____"], N["_____"],
			N["T0m00"], N["T0m00"], N["T0m00"], N["_____"],
			N["_____"], N["T0m00"], N["T0m00"], N["_____"],
			N["_____"], N["T0m00"], N["_____"], N["_____"],
			N["_____"], N["T0m00"], N["_____"], N["_____"],
			N["_____"], N["T0m00"], N["_____"], N["_____"],
			N["_____"], N["T0m00"], N["_____"], N["_____"],
			N["_____"], N["T0m00"], N["L0m00"], N["L0m00"],
			N["_____"], N["T0m00"], N["_____"], N["_____"],
			N["_____"], N["L0m00"], N["T0m00"], N["L0m00"],
			N["_____"], N["_____"], N["L0m00"], N["_____"],
			
			N["_____"], N["R0m00"], N["_____"], N["_____"],
			N["_____"], N["_____"], N["_____"], N["_____"],
			N["_____"], N["T0m00"], N["_____"], N["_____"],
			N["_____"], N["_____"], N["_____"], N["_____"],
			N["_____"], N["_____"], N["_____"], N["_____"],
			N["_____"], N["_____"], N["_____"], N["_____"],
			N["_____"], N["_____"], N["_____"], N["_____"],
			N["_____"], N["_____"], N["_____"], N["_____"],
			N["_____"], N["_____"], N["_____"], N["_____"],
			N["_____"], N["_____"], N["_____"], N["_____"],
			N["_____"], N["L0m00"], N["L0m00"], N["L0m00"],
			N["_____"], N["_____"], N["_____"], N["_____"]
		},
		yslice_prob = {
			{ypos = 0,prob = 254},
			{ypos = 1,prob = 254},
			{ypos = 2,prob = 254},
			{ypos = 3,prob = 254},
			{ypos = 4,prob = 254},
			{ypos = 5,prob = 254},
			{ypos = 6,prob = 254},
			{ypos = 7,prob = 254},
			{ypos = 8,prob = 254},
			{ypos = 9,prob = 254},
			{ypos = 10,prob = 254},
			{ypos = 11,prob = 254}
		}
	}
