


--Apple 01
	local N = gal.N

	
	return {
		size = {x = 5,y = 8,z = 5},
		data = {
			N["_____"], N["_____"], N["_____"], N["_____"], N["_____"],
			N["_____"], N["_____"], N["_____"], N["_____"], N["_____"],
			N["_____"], N["_____"], N["_____"], N["_____"], N["_____"],
			N["_____"], N["_____"], N["_____"], N["_____"], N["_____"],
			N["L0m02"], N["L0m01"], N["L0m01"], N["L0m01"], N["L0m02"],
			N["L0m02"], N["L0m01"], N["L0m01"], N["L0m01"], N["L0m02"],
			N["L0m02"], N["L0m01"], N["L0m01"], N["L0m01"], N["L0m02"],
			N["_____"], N["_____"], N["_____"], N["_____"], N["_____"],
			
			N["_____"], N["_____"], N["_____"], N["_____"], N["_____"],
			N["_____"], N["_____"], N["_____"], N["_____"], N["_____"],
			N["_____"], N["_____"], N["_____"], N["_____"], N["_____"],
			N["_____"], N["_____"], N["_____"], N["_____"], N["_____"],
			N["L0m01"], N["T0m00"], N["L0m00"], N["T0m03"], N["L0m01"],
			N["L0m01"], N["L0m00"], N["L0m00"], N["L0m00"], N["L0m01"],
			N["L0m01"], N["L0m00"], N["L0m00"], N["L0m00"], N["L0m01"],
			N["_____"], N["L0m01"], N["L0m01"], N["L0m01"], N["_____"],
			
			N["_____"], N["_____"], N["T0m00"], N["_____"], N["_____"],
			N["_____"], N["_____"], N["T0m00"], N["_____"], N["_____"],
			N["_____"], N["_____"], N["T0m00"], N["_____"], N["_____"],
			N["_____"], N["_____"], N["T0m00"], N["_____"], N["_____"],
			N["L0m01"], N["L0m00"], N["L0m00"], N["L0m00"], N["L0m01"],
			N["L0m01"], N["L0m00"], N["L0m00"], N["L0m00"], N["L0m01"],
			N["L0m01"], N["L0m00"], N["L0m00"], N["L0m00"], N["L0m01"],
			N["_____"], N["L0m01"], N["L0m00"], N["L0m01"], N["_____"],
			
			N["_____"], N["_____"], N["_____"], N["_____"], N["_____"],
			N["_____"], N["_____"], N["_____"], N["_____"], N["_____"],
			N["_____"], N["_____"], N["_____"], N["_____"], N["_____"],
			N["_____"], N["_____"], N["_____"], N["_____"], N["_____"],
			N["L0m01"], N["T0m03"], N["L0m00"], N["T0m00"], N["L0m01"],
			N["L0m01"], N["L0m00"], N["L0m00"], N["L0m00"], N["L0m01"],
			N["L0m01"], N["L0m00"], N["L0m00"], N["L0m00"], N["L0m01"],
			N["_____"], N["L0m01"], N["L0m01"], N["L0m01"], N["_____"],
			
			N["_____"], N["_____"], N["_____"], N["_____"], N["_____"],
			N["_____"], N["_____"], N["_____"], N["_____"], N["_____"],
			N["_____"], N["_____"], N["_____"], N["_____"], N["_____"],
			N["_____"], N["_____"], N["_____"], N["_____"], N["_____"],
			N["L0m02"], N["L0m01"], N["L0m01"], N["L0m01"], N["L0m02"],
			N["L0m02"], N["L0m01"], N["L0m01"], N["L0m01"], N["L0m02"],
			N["L0m02"], N["L0m01"], N["L0m01"], N["L0m01"], N["L0m02"],
			N["_____"], N["_____"], N["_____"], N["_____"], N["_____"]
		},
		yslice_prob = {
			{ypos = 0,prob = 254},
			{ypos = 1,prob = 254},
			{ypos = 2,prob = 126},
			{ypos = 3,prob = 254},
			{ypos = 4,prob = 254},
			{ypos = 5,prob = 254},
			{ypos = 6,prob = 126},
			{ypos = 7,prob = 254}
		}
	}
