		
--Bubble Coral
	local N = gal.N

	
	return {
		size = {x = 6,y = 5,z = 5},
		data = {
			N["_____"], N["T0m00"], N["T0m00"], N["T0m00"], N["_____"], N["_____"],
			N["_____"], N["_____"], N["T0m00"], N["T0m00"], N["_____"], N["_____"],
			N["_____"], N["_____"], N["T0m00"], N["_____"], N["_____"], N["_____"],
			N["_____"], N["_____"], N["_____"], N["_____"], N["_____"], N["_____"],
			N["_____"], N["_____"], N["_____"], N["_____"], N["_____"], N["_____"],

			N["_____"], N["T0m00"], N["T0m00"], N["T0m00"], N["T0m00"], N["_____"],
			N["_____"], N["T0m00"], N["T0m00"], N["T0m00"], N["T0m00"], N["_____"],
			N["_____"], N["_____"], N["T0m00"], N["T0m00"], N["_____"], N["_____"],
			N["_____"], N["_____"], N["_____"], N["_____"], N["_____"], N["_____"],
			N["_____"], N["_____"], N["_____"], N["_____"], N["_____"], N["_____"],

			N["_____"], N["T0m00"], N["T0m00"], N["T0m00"], N["T0m00"], N["_____"],
			N["_____"], N["T0m00"], N["T0m00"], N["T0m00"], N["T0m00"], N["_____"],
			N["_____"], N["_____"], N["T0m00"], N["T0m00"], N["_____"], N["_____"],
			N["_____"], N["_____"], N["T0m00"], N["T0m00"], N["_____"], N["_____"],
			N["_____"], N["_____"], N["_____"], N["_____"], N["_____"], N["_____"],

			N["_____"], N["_____"], N["T0m00"], N["T0m00"], N["_____"], N["_____"],
			N["_____"], N["_____"], N["T0m00"], N["T0m00"], N["_____"], N["_____"],
			N["_____"], N["_____"], N["_____"], N["T0m00"], N["_____"], N["_____"],
			N["_____"], N["_____"], N["_____"], N["_____"], N["_____"], N["_____"],
			N["_____"], N["_____"], N["_____"], N["_____"], N["_____"], N["_____"],

			N["_____"], N["_____"], N["T0m00"], N["T0m00"], N["_____"], N["_____"],
			N["_____"], N["_____"], N["_____"], N["_____"], N["_____"], N["_____"],
			N["_____"], N["_____"], N["_____"], N["_____"], N["_____"], N["_____"],
			N["_____"], N["_____"], N["_____"], N["_____"], N["_____"], N["_____"],
			N["_____"], N["_____"], N["_____"], N["_____"], N["_____"], N["_____"]
		},
		yslice_prob = {
			{ypos = 0,prob = 254},
			{ypos = 1,prob = 254},
			{ypos = 2,prob = 254},
			{ypos = 3,prob = 254},
			{ypos = 4,prob = 254}
		}
	}
