		
--Cactus - Joshua Tree
	local N = gal.N

	
	return {
		size = {x = 5,y = 6,z = 1},
		data = {
			N["_____"], N["_____"], N["H0m00"], N["_____"], N["_____"],
			N["_____"], N["_____"], N["H0m00"], N["_____"], N["_____"],
			N["_____"], N["_____"], N["H0m00"], N["_____"], N["_____"],
			N["H0m00"], N["H0m00"], N["H0m00"], N["H0m00"], N["H0m00"],
			N["H0m00"], N["_____"], N["H0m00"], N["_____"], N["H0m00"],
			N["_____"], N["_____"], N["H0m00"], N["_____"], N["_____"]
		},
		yslice_prob = {
			{ypos = 0,prob = 254},
			{ypos = 1,prob = 254},
			{ypos = 2,prob = 254},
			{ypos = 3,prob = 254},
			{ypos = 4,prob = 254},
			{ypos = 5,prob = 254},
		}
	}
