

--Daintree Stringybark 02 Tree
	local N = gal.N

	
	return {
	yslice_prob = {
		
	},
	size = {
		y = 31,
		x = 15,
		z = 15
	},
	data = {
		N["_____"],N["_____"],N["_____"],N["_____"],N["_____"],N["_____"],N["_____"],N["_____"],N["_____"],N["_____"],N["_____"],N["_____"],N["_____"],N["_____"],N["_____"],N["_____"],N["_____"],N["_____"],N["_____"],N["_____"],N["_____"],N["_____"],N["_____"],N["_____"],N["_____"],N["_____"],N["_____"],N["_____"],N["_____"],N["_____"],N["_____"],N["_____"],N["_____"],N["_____"],N["_____"],N["_____"],N["_____"],N["_____"],N["_____"],N["_____"],N["_____"],N["_____"],N["_____"],N["_____"],N["_____"],N["_____"],N["_____"],N["_____"],N["_____"],N["_____"],N["_____"],N["_____"],N["_____"],N["_____"],N["_____"],N["_____"],N["_____"],N["_____"],N["_____"],N["_____"],N["_____"],N["_____"],N["_____"],N["_____"],N["_____"],N["_____"],N["_____"],N["_____"],N["_____"],N["_____"],N["_____"],N["_____"],N["_____"],N["_____"],N["_____"],N["_____"],N["_____"],N["_____"],N["_____"],N["_____"],N["_____"],N["_____"],N["_____"],N["_____"],N["_____"],N["_____"],N["_____"],N["_____"],N["_____"],N["_____"],N["_____"],N["_____"],N["_____"],N["_____"],N["_____"],N["_____"],N["_____"],N["_____"],N["_____"],N["_____"],N["_____"],N["_____"],N["_____"],N["_____"],N["_____"],N["_____"],N["_____"],N["_____"],N["_____"],N["_____"],N["_____"],N["_____"],N["_____"],N["_____"],N["_____"],N["_____"],N["_____"],N["_____"],N["_____"],N["_____"],N["_____"],N["_____"],N["_____"],N["_____"],N["_____"],N["_____"],N["_____"],N["_____"],N["_____"],N["_____"],N["_____"],N["_____"],N["_____"],N["_____"],N["_____"],N["_____"],N["_____"],N["_____"],N["_____"],N["_____"],N["_____"],N["_____"],N["_____"],N["_____"],N["_____"],N["_____"],N["_____"],N["_____"],N["_____"],N["_____"],N["_____"],N["_____"],N["_____"],N["_____"],N["_____"],N["_____"],N["_____"],N["_____"],N["_____"],N["_____"],N["_____"],N["_____"],N["_____"],N["_____"],N["_____"],N["_____"],N["_____"],N["_____"],N["_____"],N["_____"],N["_____"],N["_____"],N["_____"],N["_____"],N["_____"],N["_____"],N["_____"],N["_____"],N["_____"],N["_____"],N["_____"],N["_____"],N["_____"],N["_____"],N["_____"],N["_____"],N["_____"],N["_____"],N["_____"],N["_____"],N["_____"],N["_____"],N["_____"],N["_____"],N["_____"],N["_____"],N["_____"],N["_____"],N["_____"],N["_____"],N["_____"],N["_____"],N["_____"],N["_____"],N["_____"],N["_____"],N["_____"],N["_____"],N["_____"],N["_____"],N["_____"],N["_____"],N["_____"],N["_____"],N["_____"],N["_____"],N["_____"],N["_____"],N["_____"],N["_____"],N["_____"],N["_____"],N["_____"],N["_____"],N["_____"],N["_____"],N["_____"],N["_____"],N["_____"],N["_____"],N["_____"],N["_____"],N["_____"],N["_____"],N["_____"],N["_____"],N["_____"],N["_____"],N["_____"],N["_____"],N["_____"],N["_____"],N["_____"],N["_____"],N["_____"],N["_____"],N["_____"],N["_____"],N["_____"],N["_____"],N["_____"],N["_____"],N["_____"],N["_____"],N["_____"],N["_____"],N["_____"],N["_____"],N["_____"],N["_____"],N["_____"],N["_____"],N["_____"],N["_____"],N["_____"],N["_____"],N["_____"],N["_____"],N["_____"],N["_____"],N["_____"],N["_____"],N["_____"],N["_____"],N["_____"],N["_____"],N["_____"],N["_____"],N["_____"],N["_____"],N["_____"],N["_____"],N["_____"],N["_____"],N["_____"],N["_____"],N["_____"],N["_____"],N["_____"],N["_____"],N["_____"],N["_____"],N["_____"],N["_____"],N["_____"],N["_____"],N["_____"],N["_____"],N["_____"],N["_____"],N["_____"],N["_____"],N["_____"],N["_____"],N["_____"],N["_____"],N["_____"],N["_____"],N["_____"],N["_____"],N["_____"],N["_____"],N["_____"],N["_____"],N["_____"],N["_____"],N["_____"],N["_____"],N["_____"],N["_____"],N["_____"],N["_____"],N["_____"],N["_____"],N["_____"],N["_____"],N["_____"],N["_____"],N["_____"],N["_____"],N["_____"],N["_____"],N["_____"],N["_____"],N["_____"],N["_____"],N["_____"],N["_____"],N["_____"],N["_____"],N["_____"],N["_____"],N["_____"],N["_____"],N["_____"],N["_____"],N["_____"],N["_____"],N["_____"],N["_____"],N["_____"],N["_____"],N["_____"],N["_____"],N["_____"],N["_____"],N["_____"],N["_____"],N["_____"],N["_____"],N["_____"],N["_____"],N["_____"],N["_____"],N["_____"],N["_____"],N["_____"],N["_____"],N["_____"],N["_____"],N["_____"],N["_____"],N["_____"],N["_____"],N["_____"],N["_____"],N["_____"],N["_____"],N["_____"],N["_____"],N["_____"],N["_____"],N["_____"],N["_____"],N["_____"],N["_____"],N["_____"],N["_____"],N["_____"],N["_____"],N["_____"],N["_____"],N["_____"],N["_____"],N["_____"],N["_____"],N["_____"],N["_____"],N["_____"],N["_____"],N["_____"],N["_____"],N["_____"],N["_____"],N["_____"],N["_____"],N["_____"],N["_____"],N["_____"],N["_____"],N["_____"],N["_____"],N["_____"],N["_____"],N["_____"],N["_____"],N["_____"],N["_____"],N["_____"],N["_____"],N["_____"],N["_____"],N["_____"],N["_____"],N["_____"],N["_____"],N["_____"],N["_____"],N["_____"],N["_____"],N["_____"],N["_____"],N["_____"],N["_____"],N["_____"],N["_____"],N["_____"],N["_____"],N["_____"],N["_____"],N["_____"],N["_____"],N["_____"],N["_____"],N["_____"],N["_____"],N["_____"],N["_____"],N["_____"],N["_____"],N["_____"],N["_____"],N["_____"],N["_____"],N["_____"],N["_____"],N["_____"],N["_____"],N["_____"],N["_____"],N["_____"],N["_____"],N["_____"],N["_____"],N["_____"],N["_____"],N["_____"],N["_____"],N["_____"],N["_____"],N["_____"],N["_____"],N["_____"],N["_____"],N["_____"],N["_____"],N["_____"],N["_____"],N["_____"],N["_____"],N["_____"],N["_____"],N["_____"],N["_____"],N["_____"],N["_____"],N["_____"],N["_____"],N["_____"],N["_____"],N["_____"],N["_____"],N["_____"],N["_____"],N["_____"],N["_____"],N["_____"],N["_____"],N["_____"],N["_____"],N["_____"],N["_____"],N["_____"],N["_____"],N["_____"],N["_____"],N["_____"],N["_____"],N["_____"],N["_____"],N["_____"],N["_____"],N["_____"],N["_____"],N["_____"],N["_____"],N["_____"],N["_____"],N["_____"],N["_____"],N["_____"],N["_____"],N["_____"],N["_____"],N["_____"],N["_____"],N["_____"],N["_____"],N["_____"],N["_____"],N["_____"],N["_____"],N["_____"],N["_____"],N["_____"],N["_____"],N["_____"],N["_____"],N["_____"],N["_____"],N["_____"],N["_____"],N["_____"],N["_____"],N["_____"],N["_____"],N["_____"],N["_____"],N["_____"],N["_____"],N["_____"],N["_____"],N["_____"],N["_____"],N["_____"],N["_____"],N["_____"],N["_____"],N["_____"],N["_____"],N["_____"],N["_____"],N["_____"],N["_____"],N["_____"],N["_____"],N["_____"],N["_____"],N["_____"],N["_____"],N["_____"],N["_____"],N["_____"],N["_____"],N["_____"],N["_____"],N["_____"],N["_____"],N["_____"],N["_____"],N["_____"],N["_____"],N["_____"],N["_____"],N["_____"],N["_____"],N["_____"],N["_____"],N["_____"],N["_____"],N["_____"],N["_____"],N["_____"],N["_____"],N["_____"],N["_____"],N["_____"],N["_____"],N["_____"],N["_____"],N["_____"],N["_____"],N["_____"],N["_____"],N["_____"],N["_____"],N["_____"],N["_____"],N["_____"],N["_____"],N["_____"],N["_____"],N["_____"],N["_____"],N["_____"],N["_____"],N["_____"],N["_____"],N["_____"],N["_____"],N["_____"],N["_____"],N["_____"],N["_____"],N["_____"],N["_____"],N["_____"],N["_____"],N["_____"],N["_____"],N["_____"],N["_____"],N["_____"],N["_____"],N["_____"],N["_____"],N["_____"],N["_____"],N["_____"],N["_____"],N["_____"],N["_____"],N["_____"],N["_____"],N["_____"],N["_____"],N["_____"],N["_____"],N["_____"],N["_____"],N["_____"],N["_____"],N["_____"],N["_____"],N["_____"],N["_____"],N["_____"],N["_____"],N["_____"],N["_____"],N["_____"],N["_____"],N["_____"],N["_____"],N["_____"],N["_____"],N["_____"],N["_____"],N["_____"],N["_____"],N["_____"],N["_____"],N["_____"],N["_____"],N["_____"],N["_____"],N["_____"],N["_____"],N["_____"],N["_____"],N["_____"],N["_____"],N["_____"],N["_____"],N["_____"],N["_____"],N["_____"],N["_____"],N["_____"],N["_____"],N["_____"],N["_____"],N["_____"],N["_____"],N["_____"],N["_____"],N["_____"],N["_____"],N["_____"],N["_____"],N["_____"],N["_____"],N["_____"],N["_____"],N["_____"],N["_____"],N["_____"],N["_____"],N["_____"],N["_____"],N["_____"],N["_____"],N["_____"],N["_____"],N["_____"],N["_____"],N["_____"],N["_____"],N["_____"],N["_____"],N["_____"],N["_____"],N["_____"],N["_____"],N["_____"],N["_____"],N["_____"],N["_____"],N["_____"],
		N["L0m02"],
		N["_____"],N["_____"],N["_____"],N["_____"],N["_____"],N["_____"],N["_____"],N["_____"],N["_____"],N["_____"],N["_____"],N["_____"],
		N["L0m02"],
		N["_____"],
		N["L0m02"],
		N["_____"],N["_____"],N["_____"],N["_____"],N["_____"],N["_____"],N["_____"],N["_____"],N["_____"],N["_____"],N["_____"],N["_____"],N["_____"],N["_____"],N["_____"],N["_____"],N["_____"],N["_____"],N["_____"],N["_____"],N["_____"],N["_____"],N["_____"],N["_____"],N["_____"],N["_____"],N["_____"],N["_____"],N["_____"],
		N["L0m02"],
		N["_____"],N["_____"],N["_____"],N["_____"],N["_____"],N["_____"],N["_____"],N["_____"],N["_____"],N["_____"],N["_____"],N["_____"],
		N["L0m02"],
		N["_____"],N["_____"],N["_____"],N["_____"],N["_____"],N["_____"],N["_____"],N["_____"],N["_____"],N["_____"],N["_____"],N["_____"],N["_____"],
		N["L0m02"],
		N["L0m02"],
		N["_____"],N["_____"],N["_____"],N["_____"],N["_____"],N["_____"],N["_____"],N["_____"],N["_____"],N["_____"],N["_____"],N["_____"],N["_____"],N["_____"],N["_____"],N["_____"],N["_____"],N["_____"],N["_____"],N["_____"],N["_____"],N["_____"],N["_____"],N["_____"],N["_____"],N["_____"],N["_____"],N["_____"],N["_____"],N["_____"],N["_____"],N["_____"],N["_____"],N["_____"],N["_____"],N["_____"],N["_____"],N["_____"],N["_____"],N["_____"],N["_____"],N["_____"],N["_____"],N["_____"],N["_____"],N["_____"],N["_____"],N["_____"],N["_____"],N["_____"],N["_____"],N["_____"],N["_____"],N["_____"],N["_____"],N["_____"],N["_____"],N["_____"],N["_____"],N["_____"],N["_____"],N["_____"],N["_____"],N["_____"],N["_____"],N["_____"],N["_____"],N["_____"],N["_____"],N["_____"],N["_____"],N["_____"],N["_____"],N["_____"],N["_____"],N["_____"],N["_____"],N["_____"],N["_____"],N["_____"],N["_____"],N["_____"],N["_____"],N["_____"],N["_____"],N["_____"],N["_____"],N["_____"],N["_____"],N["_____"],N["_____"],N["_____"],N["_____"],N["_____"],N["_____"],N["_____"],N["_____"],N["_____"],N["_____"],N["_____"],N["_____"],N["_____"],N["_____"],N["_____"],N["_____"],N["_____"],N["_____"],N["_____"],N["_____"],N["_____"],N["_____"],N["_____"],N["_____"],N["_____"],N["_____"],N["_____"],N["_____"],N["_____"],N["_____"],N["_____"],N["_____"],N["_____"],N["_____"],N["_____"],N["_____"],N["_____"],N["_____"],N["_____"],N["_____"],N["_____"],N["_____"],N["_____"],N["_____"],N["_____"],N["_____"],N["_____"],N["_____"],N["_____"],N["_____"],N["_____"],N["_____"],N["_____"],N["_____"],N["_____"],N["_____"],N["_____"],N["_____"],N["_____"],N["_____"],N["_____"],N["_____"],N["_____"],N["_____"],N["_____"],N["_____"],N["_____"],N["_____"],N["_____"],N["_____"],N["_____"],N["_____"],N["_____"],N["_____"],N["_____"],N["_____"],N["_____"],N["_____"],N["_____"],N["_____"],N["_____"],N["_____"],N["_____"],N["_____"],N["_____"],N["_____"],N["_____"],N["_____"],N["_____"],N["_____"],N["_____"],N["_____"],N["_____"],N["_____"],N["_____"],N["_____"],N["_____"],N["_____"],N["_____"],N["_____"],N["_____"],N["_____"],N["_____"],N["_____"],N["_____"],N["_____"],N["_____"],N["_____"],N["_____"],N["_____"],N["_____"],N["_____"],N["_____"],N["_____"],N["_____"],N["_____"],N["_____"],N["_____"],N["_____"],N["_____"],N["_____"],N["_____"],N["_____"],N["_____"],N["_____"],N["_____"],N["_____"],N["_____"],N["_____"],N["_____"],N["_____"],N["_____"],N["_____"],N["_____"],N["_____"],N["_____"],N["_____"],N["_____"],N["_____"],N["_____"],N["_____"],N["_____"],N["_____"],N["_____"],N["_____"],N["_____"],N["_____"],N["_____"],N["_____"],N["_____"],N["_____"],N["_____"],N["_____"],N["_____"],N["_____"],N["_____"],N["_____"],N["_____"],N["_____"],N["_____"],N["_____"],N["_____"],N["_____"],N["_____"],N["_____"],N["_____"],N["_____"],N["_____"],N["_____"],N["_____"],N["_____"],N["_____"],N["_____"],N["_____"],N["_____"],N["_____"],N["_____"],N["_____"],N["_____"],N["_____"],N["_____"],N["_____"],N["_____"],N["_____"],N["_____"],N["_____"],N["_____"],N["_____"],N["_____"],N["_____"],N["_____"],N["_____"],N["_____"],N["_____"],N["_____"],N["_____"],N["_____"],N["_____"],N["_____"],N["_____"],N["_____"],N["_____"],N["_____"],N["_____"],N["_____"],N["_____"],N["_____"],N["_____"],N["_____"],N["_____"],N["_____"],N["_____"],N["_____"],N["_____"],N["_____"],N["_____"],N["_____"],N["_____"],N["_____"],N["_____"],N["_____"],N["_____"],N["_____"],N["_____"],N["_____"],N["_____"],N["_____"],N["_____"],N["_____"],N["_____"],N["_____"],N["_____"],N["_____"],N["_____"],N["_____"],N["_____"],N["_____"],N["_____"],N["_____"],N["_____"],N["_____"],N["_____"],N["_____"],N["_____"],N["_____"],N["_____"],N["_____"],N["_____"],N["_____"],N["_____"],N["_____"],N["_____"],N["_____"],N["_____"],N["_____"],N["_____"],N["_____"],N["_____"],N["_____"],N["_____"],N["_____"],N["_____"],N["_____"],N["_____"],N["_____"],N["_____"],N["_____"],N["_____"],N["_____"],N["_____"],N["_____"],
		N["L0m02"],
		N["L0m02"],
		N["L0m02"],
		N["_____"],N["_____"],N["_____"],N["_____"],N["_____"],N["_____"],N["_____"],N["_____"],N["_____"],N["_____"],
		N["L0m02"],
		N["L0m02"],
		N["L0m02"],
		N["L0m02"],
		N["L0m02"],
		N["L0m02"],
		N["_____"],N["_____"],N["_____"],N["_____"],N["_____"],N["_____"],N["_____"],N["_____"],
		N["L0m02"],
		N["L0m02"],
		N["L0m02"],
		N["L0m02"],
		N["L0m01"],
		N["L0m02"],
		N["L0m02"],
		N["_____"],N["_____"],N["_____"],N["_____"],N["_____"],N["_____"],N["_____"],N["_____"],
		N["L0m02"],
		N["L0m02"],
		N["L0m01"],
		N["L0m02"],
		N["L0m01"],
		N["L0m02"],
		N["L0m02"],
		N["_____"],N["_____"],N["_____"],N["_____"],N["_____"],N["_____"],N["_____"],N["_____"],
		N["L0m02"],
		N["L0m02"],
		N["L0m02"],
		N["L0m02"],
		N["L0m02"],
		N["L0m02"],
		N["L0m02"],
		N["_____"],N["_____"],N["_____"],N["_____"],N["_____"],N["_____"],N["_____"],N["_____"],
		N["L0m02"],
		N["L0m02"],
		N["L0m02"],
		N["L0m02"],
		N["L0m01"],
		N["L0m02"],
		N["L0m02"],
		N["_____"],N["_____"],N["_____"],N["_____"],N["_____"],N["_____"],N["_____"],
		N["L0m02"],
		N["L0m02"],
		N["L0m02"],
		N["L0m01"],
		N["L0m02"],
		N["L0m02"],
		N["L0m02"],
		N["L0m02"],
		N["_____"],N["_____"],N["_____"],N["_____"],N["_____"],N["_____"],N["_____"],
		N["L0m02"],
		N["L0m02"],
		N["L0m01"],
		N["L0m01"],
		N["L0m02"],
		N["L0m02"],
		N["L0m02"],
		N["_____"],N["_____"],N["_____"],N["_____"],N["_____"],N["_____"],N["_____"],N["_____"],
		N["L0m02"],
		N["L0m02"],
		N["L0m02"],
		N["L0m02"],
		N["L0m02"],
		N["L0m02"],
		N["_____"],N["_____"],N["_____"],N["_____"],N["_____"],N["_____"],N["_____"],N["_____"],N["_____"],N["_____"],
		N["L0m02"],
		N["L0m02"],
		N["L0m02"],
		N["L0m02"],
		N["_____"],N["_____"],N["_____"],N["_____"],N["_____"],N["_____"],N["_____"],N["_____"],N["_____"],N["_____"],N["_____"],N["_____"],N["_____"],
		N["L0m02"],
		N["_____"],N["_____"],N["_____"],N["_____"],N["_____"],N["_____"],N["_____"],N["_____"],N["_____"],N["_____"],N["_____"],N["_____"],N["_____"],N["_____"],
		N["L0m02"],
		N["_____"],N["_____"],N["_____"],N["_____"],N["_____"],N["_____"],N["_____"],N["_____"],N["_____"],N["_____"],N["_____"],N["_____"],N["_____"],N["_____"],N["_____"],N["_____"],N["_____"],N["_____"],N["_____"],N["_____"],N["_____"],N["_____"],N["_____"],N["_____"],N["_____"],N["_____"],N["_____"],N["_____"],N["_____"],N["_____"],N["_____"],N["_____"],N["_____"],N["_____"],N["_____"],N["_____"],N["_____"],N["_____"],N["_____"],N["_____"],N["_____"],N["_____"],N["_____"],N["_____"],N["_____"],N["_____"],N["_____"],N["_____"],N["_____"],N["_____"],N["_____"],N["_____"],N["_____"],N["_____"],N["_____"],N["_____"],N["_____"],N["_____"],N["_____"],N["_____"],N["_____"],N["_____"],N["_____"],N["_____"],N["_____"],N["_____"],N["_____"],N["_____"],N["_____"],N["_____"],N["_____"],N["_____"],N["_____"],N["_____"],N["_____"],N["_____"],N["_____"],N["_____"],N["_____"],N["_____"],N["_____"],N["_____"],N["_____"],N["_____"],N["_____"],N["_____"],N["_____"],N["_____"],N["_____"],N["_____"],N["_____"],N["_____"],N["_____"],N["_____"],N["_____"],N["_____"],N["_____"],N["_____"],N["_____"],N["_____"],N["_____"],N["_____"],N["_____"],N["_____"],N["_____"],N["_____"],N["_____"],N["_____"],N["_____"],N["_____"],N["_____"],N["_____"],N["_____"],N["_____"],N["_____"],N["_____"],N["_____"],N["_____"],N["_____"],N["_____"],N["_____"],N["_____"],N["_____"],N["_____"],N["_____"],N["_____"],N["_____"],N["_____"],N["_____"],N["_____"],N["_____"],N["_____"],N["_____"],N["_____"],N["_____"],N["_____"],N["_____"],N["_____"],N["_____"],N["_____"],N["_____"],N["_____"],N["_____"],N["_____"],N["_____"],N["_____"],N["_____"],N["_____"],N["_____"],N["_____"],N["_____"],N["_____"],N["_____"],N["_____"],N["_____"],N["_____"],N["_____"],N["_____"],N["_____"],N["_____"],N["_____"],N["_____"],N["_____"],N["_____"],N["_____"],N["_____"],N["_____"],N["_____"],N["_____"],N["_____"],N["_____"],N["_____"],N["_____"],N["_____"],N["_____"],N["_____"],N["_____"],N["_____"],N["_____"],N["_____"],N["_____"],N["_____"],N["_____"],N["_____"],N["_____"],N["_____"],N["_____"],N["_____"],N["_____"],N["_____"],N["_____"],N["_____"],N["_____"],N["_____"],N["_____"],N["_____"],N["_____"],N["_____"],N["_____"],N["_____"],N["_____"],N["_____"],N["_____"],N["_____"],N["_____"],N["_____"],N["_____"],N["_____"],N["_____"],N["_____"],N["_____"],N["_____"],N["_____"],N["_____"],N["_____"],N["_____"],N["_____"],N["_____"],N["_____"],N["_____"],N["_____"],N["_____"],N["_____"],N["_____"],N["_____"],N["_____"],N["_____"],N["_____"],N["_____"],N["_____"],N["_____"],N["_____"],N["_____"],N["_____"],N["_____"],N["_____"],N["_____"],N["_____"],N["_____"],N["_____"],N["_____"],N["_____"],N["_____"],N["_____"],N["_____"],N["_____"],N["_____"],N["_____"],N["_____"],N["_____"],N["_____"],N["_____"],N["_____"],N["_____"],N["_____"],N["_____"],N["_____"],N["_____"],N["_____"],N["_____"],N["_____"],N["_____"],N["_____"],N["_____"],N["_____"],N["_____"],N["_____"],N["_____"],N["_____"],N["_____"],N["_____"],N["_____"],N["_____"],N["_____"],N["_____"],N["_____"],N["_____"],N["_____"],N["_____"],N["_____"],N["_____"],N["_____"],N["_____"],N["_____"],N["_____"],N["_____"],N["_____"],N["_____"],N["_____"],N["_____"],N["_____"],N["_____"],N["_____"],N["_____"],N["_____"],N["_____"],N["_____"],N["_____"],
		N["L0m02"],
		N["L0m02"],
		N["L0m02"],
		N["L0m02"],
		N["L0m02"],
		N["L0m02"],
		N["_____"],N["_____"],N["_____"],N["_____"],N["_____"],N["_____"],N["_____"],N["_____"],
		N["L0m02"],
		N["L0m02"],
		N["L0m02"],
		N["L0m01"],
		N["L0m01"],
		N["L0m01"],
		N["L0m02"],
		N["_____"],N["_____"],N["_____"],N["_____"],N["_____"],N["_____"],N["_____"],
		N["L0m02"],
		N["L0m02"],
		N["L0m01"],
		N["L0m01"],
		N["L0m01"],
		N["L0m00"],
		N["L0m01"],
		N["L0m02"],
		N["_____"],N["_____"],N["_____"],N["_____"],N["_____"],N["_____"],N["_____"],
		N["L0m02"],
		N["L0m02"],
		N["L0m01"],
		N["L0m00"],
		N["L0m01"],
		N["L0m00"],
		N["L0m01"],
		N["L0m02"],
		N["_____"],N["_____"],N["_____"],N["_____"],N["_____"],N["_____"],N["_____"],
		N["L0m02"],
		N["L0m02"],
		N["L0m01"],
		N["L0m01"],
		N["L0m01"],
		N["L0m01"],
		N["L0m01"],
		N["L0m02"],
		N["_____"],N["_____"],N["_____"],N["_____"],N["_____"],N["_____"],N["_____"],
		N["L0m02"],
		N["L0m02"],
		N["L0m01"],
		N["L0m01"],
		N["L0m01"],
		N["L0m00"],
		N["L0m01"],
		N["L0m02"],
		N["_____"],N["_____"],N["_____"],N["_____"],N["_____"],N["_____"],N["_____"],
		N["L0m02"],
		N["L0m01"],
		N["L0m01"],
		N["L0m00"],
		N["L0m01"],
		N["L0m01"],
		N["L0m01"],
		N["L0m02"],
		N["_____"],N["_____"],N["_____"],N["_____"],N["_____"],N["_____"],
		N["L0m02"],
		N["L0m02"],
		N["L0m01"],
		N["L0m00"],
		N["L0m00"],
		N["L0m01"],
		N["L0m02"],
		N["L0m02"],
		N["L0m02"],
		N["_____"],N["_____"],N["_____"],N["_____"],N["_____"],N["_____"],
		N["L0m02"],
		N["L0m02"],
		N["L0m01"],
		N["L0m01"],
		N["L0m01"],
		N["L0m01"],
		N["L0m02"],
		N["L0m02"],
		N["_____"],N["_____"],N["_____"],N["_____"],N["_____"],N["_____"],N["_____"],
		N["L0m02"],
		N["L0m02"],
		N["L0m02"],
		N["L0m02"],
		N["L0m01"],
		N["L0m02"],
		N["L0m02"],
		N["L0m02"],
		N["_____"],N["_____"],N["_____"],N["_____"],N["_____"],N["_____"],N["_____"],N["_____"],
		N["L0m02"],
		N["L0m02"],
		N["L0m02"],
		N["L0m01"],
		N["L0m02"],
		N["L0m02"],
		N["_____"],N["_____"],N["_____"],N["_____"],N["_____"],N["_____"],N["_____"],N["_____"],N["_____"],N["_____"],
		N["L0m02"],
		N["L0m02"],
		N["L0m01"],
		N["L0m02"],
		N["L0m02"],
		N["_____"],N["_____"],N["_____"],N["_____"],N["_____"],N["_____"],N["_____"],N["_____"],N["_____"],N["_____"],
		N["L0m02"],
		N["L0m02"],
		N["L0m02"],
		N["L0m02"],
		N["L0m02"],
		N["_____"],N["_____"],N["_____"],N["_____"],N["_____"],N["_____"],N["_____"],N["_____"],N["_____"],N["_____"],N["_____"],
		N["L0m02"],
		N["L0m02"],
		N["L0m02"],
		N["_____"],N["_____"],N["_____"],N["_____"],N["_____"],N["_____"],N["_____"],N["_____"],N["_____"],N["_____"],N["_____"],N["_____"],N["_____"],N["_____"],N["_____"],N["_____"],N["_____"],N["_____"],N["_____"],N["_____"],N["_____"],N["_____"],N["_____"],N["_____"],N["_____"],N["_____"],N["_____"],N["_____"],N["_____"],N["_____"],N["_____"],N["_____"],N["_____"],N["_____"],N["_____"],N["_____"],N["_____"],N["_____"],N["_____"],N["_____"],N["_____"],N["_____"],N["_____"],N["_____"],N["_____"],N["_____"],N["_____"],N["_____"],N["_____"],N["_____"],N["_____"],N["_____"],N["_____"],N["_____"],N["_____"],N["_____"],N["_____"],N["_____"],N["_____"],N["_____"],N["_____"],N["_____"],N["_____"],N["_____"],N["_____"],N["_____"],N["_____"],N["_____"],N["_____"],N["_____"],N["_____"],N["_____"],N["_____"],N["_____"],N["_____"],N["_____"],N["_____"],N["_____"],N["_____"],N["_____"],N["_____"],N["_____"],N["_____"],N["_____"],N["_____"],N["_____"],N["_____"],N["_____"],N["_____"],N["_____"],N["_____"],N["_____"],N["_____"],N["_____"],N["_____"],N["_____"],N["_____"],N["_____"],N["_____"],N["_____"],N["_____"],N["_____"],N["_____"],N["_____"],N["_____"],N["_____"],N["_____"],N["_____"],N["_____"],N["_____"],N["_____"],N["_____"],N["_____"],N["_____"],N["_____"],N["_____"],N["_____"],N["_____"],N["_____"],N["_____"],N["_____"],N["_____"],N["_____"],N["_____"],N["_____"],N["_____"],N["_____"],N["_____"],N["_____"],N["_____"],N["_____"],N["_____"],N["_____"],N["_____"],N["_____"],N["_____"],N["_____"],N["_____"],N["_____"],N["_____"],N["_____"],N["_____"],N["_____"],N["_____"],N["_____"],N["_____"],N["_____"],N["_____"],N["_____"],N["_____"],N["_____"],N["_____"],N["_____"],N["_____"],N["_____"],N["_____"],N["_____"],N["_____"],N["_____"],N["_____"],N["_____"],N["_____"],N["_____"],N["_____"],N["_____"],N["_____"],N["_____"],N["_____"],N["_____"],N["_____"],N["_____"],N["_____"],N["_____"],N["_____"],N["_____"],N["_____"],N["_____"],N["_____"],N["_____"],N["_____"],N["_____"],N["_____"],N["_____"],N["_____"],N["_____"],N["_____"],N["_____"],N["_____"],N["_____"],N["_____"],N["_____"],N["_____"],N["_____"],N["_____"],N["_____"],N["_____"],N["_____"],N["_____"],N["_____"],N["_____"],N["_____"],N["_____"],N["_____"],N["_____"],N["_____"],N["_____"],N["_____"],N["_____"],N["_____"],N["_____"],N["_____"],N["_____"],N["_____"],N["_____"],N["_____"],N["_____"],N["_____"],N["_____"],N["_____"],N["_____"],N["_____"],N["_____"],N["_____"],N["_____"],N["_____"],N["_____"],N["_____"],N["_____"],N["_____"],N["_____"],N["_____"],N["_____"],N["_____"],N["_____"],N["_____"],N["_____"],
		N["L0m02"],
		N["L0m02"],
		N["L0m02"],
		N["_____"],N["_____"],N["_____"],N["_____"],N["_____"],N["_____"],N["_____"],N["_____"],N["_____"],N["_____"],N["_____"],
		N["L0m02"],
		N["L0m02"],
		N["L0m02"],
		N["L0m02"],
		N["L0m02"],
		N["L0m02"],
		N["_____"],N["_____"],N["_____"],N["_____"],N["_____"],N["_____"],N["_____"],N["_____"],N["_____"],
		N["L0m02"],
		N["L0m02"],
		N["L0m01"],
		N["L0m02"],
		N["L0m02"],
		N["L0m01"],
		N["L0m02"],
		N["L0m02"],
		N["_____"],N["_____"],N["_____"],N["_____"],N["_____"],N["_____"],N["_____"],
		N["L0m02"],
		N["L0m02"],
		N["L0m01"],
		N["L0m01"],
		N["L0m01"],
		N["L0m00"],
		N["L0m01"],
		N["L0m02"],
		N["L0m02"],
		N["_____"],N["_____"],N["_____"],N["_____"],N["_____"],N["_____"],
		N["L0m02"],
		N["L0m01"],
		N["L0m01"],
		N["L0m00"],
		N["L0m00"],
		N["T0m00"],
		N["L0m00"],
		N["L0m01"],
		N["L0m02"],
		N["_____"],N["_____"],N["_____"],N["_____"],N["_____"],
		N["L0m02"],
		N["L0m02"],
		N["L0m01"],
		N["L0m00"],
		N["T0m00"],
		N["L0m00"],
		N["T0m00"],
		N["L0m00"],
		N["L0m01"],
		N["L0m02"],
		N["_____"],N["_____"],N["_____"],N["_____"],N["_____"],
		N["L0m02"],
		N["L0m02"],
		N["L0m01"],
		N["L0m01"],
		N["L0m00"],
		N["L0m01"],
		N["L0m00"],
		N["L0m01"],
		N["L0m02"],
		N["_____"],N["_____"],N["_____"],N["_____"],N["_____"],N["_____"],
		N["L0m02"],
		N["L0m02"],
		N["L0m02"],
		N["L0m01"],
		N["L0m00"],
		N["L0m00"],
		N["T0m00"],
		N["L0m00"],
		N["L0m01"],
		N["L0m02"],
		N["_____"],N["_____"],N["_____"],N["_____"],N["_____"],
		N["L0m02"],
		N["L0m02"],
		N["L0m01"],
		N["L0m00"],
		N["T0m00"],
		N["L0m00"],
		N["L0m00"],
		N["L0m01"],
		N["L0m02"],
		N["_____"],N["_____"],N["_____"],N["_____"],N["_____"],
		N["L0m02"],
		N["L0m02"],
		N["L0m01"],
		N["L0m00"],
		N["T0m00"],
		N["T0m00"],
		N["L0m00"],
		N["L0m01"],
		N["L0m02"],
		N["L0m02"],
		N["_____"],N["_____"],N["_____"],N["_____"],N["_____"],
		N["L0m02"],
		N["L0m02"],
		N["L0m01"],
		N["L0m00"],
		N["L0m00"],
		N["L0m00"],
		N["L0m00"],
		N["L0m01"],
		N["L0m02"],
		N["_____"],N["_____"],N["_____"],N["_____"],N["_____"],N["_____"],
		N["L0m02"],
		N["L0m02"],
		N["L0m01"],
		N["L0m01"],
		N["L0m01"],
		N["L0m00"],
		N["L0m01"],
		N["L0m01"],
		N["L0m02"],
		N["_____"],N["_____"],N["_____"],N["_____"],N["_____"],N["_____"],N["_____"],
		N["L0m02"],
		N["L0m02"],
		N["L0m02"],
		N["L0m01"],
		N["L0m00"],
		N["L0m01"],
		N["L0m02"],
		N["L0m02"],
		N["_____"],N["_____"],N["_____"],N["_____"],N["_____"],N["_____"],N["_____"],N["_____"],N["_____"],
		N["L0m02"],
		N["L0m01"],
		N["L0m00"],
		N["L0m01"],
		N["L0m02"],
		N["_____"],N["_____"],N["_____"],N["_____"],N["_____"],N["_____"],N["_____"],N["_____"],N["_____"],N["_____"],
		N["L0m02"],
		N["L0m01"],
		N["L0m01"],
		N["L0m01"],
		N["L0m02"],
		N["_____"],N["_____"],N["_____"],N["_____"],N["_____"],N["_____"],N["_____"],N["_____"],N["_____"],N["_____"],
		N["L0m02"],
		N["L0m02"],
		N["L0m02"],
		N["L0m02"],
		N["L0m02"],
		N["_____"],N["_____"],N["_____"],N["_____"],N["_____"],N["_____"],N["_____"],N["_____"],N["_____"],N["_____"],N["_____"],N["_____"],N["_____"],N["_____"],N["_____"],N["_____"],N["_____"],N["_____"],N["_____"],N["_____"],N["_____"],N["_____"],N["_____"],N["_____"],N["_____"],N["_____"],N["_____"],N["_____"],N["_____"],N["_____"],N["_____"],N["_____"],N["_____"],N["_____"],N["_____"],N["_____"],N["_____"],N["_____"],N["_____"],N["_____"],N["_____"],N["_____"],N["_____"],N["_____"],N["_____"],N["_____"],N["_____"],N["_____"],N["_____"],N["_____"],N["_____"],N["_____"],N["_____"],N["_____"],N["_____"],N["_____"],N["_____"],N["_____"],N["_____"],N["_____"],N["_____"],N["_____"],N["_____"],N["_____"],N["_____"],N["_____"],N["_____"],N["_____"],N["_____"],N["_____"],N["_____"],N["_____"],N["_____"],N["_____"],N["_____"],N["_____"],N["_____"],N["_____"],N["_____"],N["_____"],N["_____"],N["_____"],N["_____"],N["_____"],N["_____"],N["_____"],N["_____"],N["_____"],N["_____"],N["_____"],N["_____"],N["_____"],N["_____"],N["_____"],N["_____"],N["_____"],N["_____"],N["_____"],N["_____"],N["_____"],N["_____"],N["_____"],N["_____"],N["_____"],N["_____"],N["_____"],N["_____"],N["_____"],N["_____"],N["_____"],N["_____"],N["_____"],N["_____"],N["_____"],N["_____"],N["_____"],N["_____"],N["_____"],N["_____"],N["_____"],N["_____"],N["_____"],N["_____"],N["_____"],N["_____"],N["_____"],N["_____"],N["_____"],N["_____"],N["_____"],N["_____"],N["_____"],N["_____"],N["_____"],N["_____"],N["_____"],N["_____"],N["_____"],N["_____"],N["_____"],N["_____"],N["_____"],N["_____"],N["_____"],N["_____"],N["_____"],N["_____"],N["_____"],N["_____"],N["_____"],N["_____"],N["_____"],N["_____"],N["_____"],N["_____"],N["_____"],N["_____"],N["_____"],N["_____"],N["_____"],N["_____"],N["_____"],N["_____"],N["_____"],N["_____"],N["_____"],N["_____"],N["_____"],N["_____"],N["_____"],N["_____"],N["_____"],N["_____"],N["_____"],N["_____"],N["_____"],N["_____"],N["_____"],N["_____"],N["_____"],N["_____"],N["_____"],N["_____"],N["_____"],N["_____"],N["_____"],N["_____"],N["_____"],N["_____"],N["_____"],N["_____"],N["_____"],N["_____"],N["_____"],N["_____"],N["_____"],N["_____"],N["_____"],N["_____"],N["_____"],N["_____"],N["_____"],N["_____"],N["_____"],N["_____"],N["_____"],N["_____"],N["_____"],N["_____"],N["_____"],N["_____"],N["_____"],N["_____"],N["_____"],N["_____"],N["_____"],N["_____"],N["_____"],N["_____"],N["_____"],
		N["L0m02"],
		N["L0m02"],
		N["L0m02"],
		N["_____"],N["_____"],N["_____"],N["_____"],N["_____"],N["_____"],N["_____"],N["_____"],N["_____"],N["_____"],N["_____"],
		N["L0m02"],
		N["L0m02"],
		N["L0m02"],
		N["L0m02"],
		N["L0m02"],
		N["_____"],N["_____"],N["_____"],N["_____"],N["_____"],N["_____"],N["_____"],N["_____"],N["_____"],N["_____"],
		N["L0m02"],
		N["L0m01"],
		N["L0m01"],
		N["L0m01"],
		N["L0m02"],
		N["_____"],N["_____"],N["_____"],N["_____"],N["_____"],N["_____"],N["_____"],N["_____"],N["_____"],N["_____"],
		N["L0m02"],
		N["L0m01"],
		N["L0m00"],
		N["L0m01"],
		N["L0m02"],
		N["L0m02"],
		N["L0m02"],
		N["L0m02"],
		N["L0m02"],
		N["_____"],N["_____"],N["_____"],N["_____"],N["_____"],
		N["L0m02"],
		N["L0m02"],
		N["L0m01"],
		N["L0m01"],
		N["L0m00"],
		N["L0m01"],
		N["L0m01"],
		N["L0m01"],
		N["L0m01"],
		N["L0m02"],
		N["_____"],N["_____"],N["_____"],N["_____"],N["_____"],
		N["L0m02"],
		N["L0m02"],
		N["L0m01"],
		N["L0m00"],
		N["T0m00"],
		N["L0m00"],
		N["L0m00"],
		N["L0m00"],
		N["L0m01"],
		N["L0m02"],
		N["_____"],N["_____"],N["_____"],N["_____"],N["_____"],
		N["L0m02"],
		N["L0m01"],
		N["L0m00"],
		N["T0m00"],
		N["L0m00"],
		N["L0m01"],
		N["L0m00"],
		N["L0m01"],
		N["L0m01"],
		N["L0m02"],
		N["_____"],N["_____"],N["_____"],N["_____"],N["_____"],
		N["L0m02"],
		N["L0m01"],
		N["L0m00"],
		N["L0m00"],
		N["L0m01"],
		N["L0m01"],
		N["L0m00"],
		N["L0m01"],
		N["L0m02"],
		N["L0m02"],
		N["_____"],N["_____"],N["_____"],N["_____"],N["_____"],
		N["L0m02"],
		N["L0m01"],
		N["L0m01"],
		N["L0m01"],
		N["L0m00"],
		N["L0m00"],
		N["T0m00"],
		N["L0m00"],
		N["L0m01"],
		N["L0m02"],
		N["_____"],N["_____"],N["_____"],N["_____"],
		N["L0m02"],
		N["L0m02"],
		N["L0m02"],
		N["L0m01"],
		N["L0m01"],
		N["L0m00"],
		N["L0m01"],
		N["L0m00"],
		N["L0m01"],
		N["L0m02"],
		N["L0m02"],
		N["_____"],N["_____"],N["_____"],N["_____"],
		N["L0m02"],
		N["L0m01"],
		N["L0m01"],
		N["L0m00"],
		N["L0m00"],
		N["L0m00"],
		N["L0m00"],
		N["L0m01"],
		N["L0m01"],
		N["L0m02"],
		N["L0m02"],
		N["_____"],N["_____"],N["_____"],N["_____"],
		N["L0m02"],
		N["L0m01"],
		N["L0m00"],
		N["T0m00"],
		N["L0m00"],
		N["L0m00"],
		N["T0m00"],
		N["L0m00"],
		N["L0m01"],
		N["L0m02"],
		N["L0m02"],
		N["_____"],N["_____"],N["_____"],N["_____"],
		N["L0m02"],
		N["L0m01"],
		N["L0m01"],
		N["L0m00"],
		N["L0m00"],
		N["T0m00"],
		N["L0m00"],
		N["L0m01"],
		N["L0m02"],
		N["L0m02"],
		N["_____"],N["_____"],N["_____"],N["_____"],N["_____"],
		N["L0m02"],
		N["L0m02"],
		N["L0m02"],
		N["L0m01"],
		N["L0m00"],
		N["T0m00"],
		N["L0m00"],
		N["L0m01"],
		N["L0m02"],
		N["L0m02"],
		N["_____"],N["_____"],N["_____"],N["_____"],N["_____"],N["_____"],N["_____"],
		N["L0m02"],
		N["L0m01"],
		N["L0m00"],
		N["T0m00"],
		N["L0m00"],
		N["L0m01"],
		N["L0m02"],
		N["L0m02"],
		N["_____"],N["_____"],N["_____"],N["_____"],N["_____"],N["_____"],N["_____"],N["_____"],
		N["L0m02"],
		N["L0m01"],
		N["L0m00"],
		N["L0m01"],
		N["L0m02"],
		N["L0m02"],
		N["L0m02"],
		N["_____"],N["_____"],N["_____"],N["_____"],N["_____"],N["_____"],N["_____"],N["_____"],
		N["L0m02"],
		N["L0m02"],
		N["L0m01"],
		N["L0m02"],
		N["L0m02"],
		N["L0m02"],
		N["_____"],N["_____"],N["_____"],N["_____"],N["_____"],N["_____"],N["_____"],N["_____"],N["_____"],N["_____"],N["_____"],
		N["L0m02"],
		N["_____"],N["_____"],N["_____"],N["_____"],N["_____"],N["_____"],N["_____"],N["_____"],N["_____"],N["_____"],N["_____"],N["_____"],N["_____"],N["_____"],N["_____"],N["_____"],N["_____"],N["_____"],N["_____"],N["_____"],N["_____"],N["_____"],N["_____"],N["_____"],N["_____"],N["_____"],N["_____"],N["_____"],N["_____"],N["_____"],N["_____"],N["_____"],N["_____"],N["_____"],N["_____"],N["_____"],N["_____"],N["_____"],N["_____"],N["_____"],N["_____"],N["_____"],N["_____"],N["_____"],N["_____"],N["_____"],N["_____"],N["_____"],N["_____"],N["_____"],N["_____"],N["_____"],N["_____"],N["_____"],N["_____"],N["_____"],N["_____"],N["_____"],N["_____"],N["_____"],N["_____"],N["_____"],N["_____"],N["_____"],N["_____"],N["_____"],N["_____"],N["_____"],N["_____"],N["_____"],N["_____"],N["_____"],N["_____"],N["_____"],N["_____"],N["_____"],N["_____"],N["_____"],N["_____"],N["_____"],N["_____"],N["_____"],N["_____"],N["_____"],N["_____"],N["_____"],N["_____"],N["_____"],N["_____"],N["_____"],N["_____"],N["_____"],N["_____"],N["_____"],N["_____"],N["_____"],N["_____"],N["_____"],N["_____"],N["_____"],N["_____"],N["_____"],N["_____"],N["_____"],N["_____"],N["_____"],N["_____"],N["_____"],N["_____"],N["_____"],N["_____"],N["_____"],N["_____"],N["_____"],N["_____"],N["_____"],N["_____"],N["_____"],N["_____"],N["_____"],N["_____"],N["_____"],N["_____"],N["_____"],N["_____"],N["_____"],N["_____"],N["_____"],N["_____"],N["_____"],N["_____"],N["_____"],N["_____"],N["_____"],N["_____"],N["_____"],N["_____"],N["_____"],N["_____"],N["_____"],N["_____"],N["_____"],N["_____"],N["_____"],N["_____"],N["_____"],N["_____"],N["_____"],N["_____"],N["_____"],N["_____"],N["_____"],N["_____"],N["_____"],N["_____"],N["_____"],N["_____"],N["_____"],N["_____"],N["_____"],N["_____"],N["_____"],N["_____"],N["_____"],N["_____"],N["_____"],N["_____"],N["_____"],N["_____"],N["_____"],N["_____"],N["_____"],N["_____"],N["_____"],N["_____"],N["_____"],N["_____"],N["_____"],N["_____"],N["_____"],N["_____"],N["_____"],N["_____"],N["_____"],N["_____"],N["_____"],N["_____"],N["_____"],N["_____"],N["_____"],N["_____"],N["_____"],N["_____"],N["_____"],N["_____"],N["_____"],N["_____"],N["_____"],N["_____"],N["_____"],N["_____"],N["_____"],N["_____"],N["_____"],N["_____"],N["_____"],
		N["L0m02"],
		N["L0m02"],
		N["L0m02"],
		N["L0m02"],
		N["L0m02"],
		N["_____"],N["_____"],N["_____"],N["_____"],N["_____"],N["_____"],N["_____"],N["_____"],N["_____"],N["_____"],
		N["L0m02"],
		N["L0m01"],
		N["L0m01"],
		N["L0m01"],
		N["L0m02"],
		N["L0m02"],
		N["L0m02"],
		N["_____"],N["_____"],N["_____"],N["_____"],N["_____"],N["_____"],N["_____"],
		N["L0m02"],
		N["L0m02"],
		N["L0m01"],
		N["L0m00"],
		N["L0m01"],
		N["L0m02"],
		N["L0m02"],
		N["L0m02"],
		N["L0m02"],
		N["_____"],N["_____"],N["_____"],N["_____"],N["_____"],
		N["L0m02"],
		N["L0m02"],
		N["L0m01"],
		N["L0m00"],
		N["T0m00"],
		N["L0m00"],
		N["L0m01"],
		N["L0m01"],
		N["L0m01"],
		N["L0m02"],
		N["L0m02"],
		N["_____"],N["_____"],N["_____"],N["_____"],
		N["L0m02"],
		N["L0m02"],
		N["L0m01"],
		N["L0m01"],
		N["L0m00"],
		N["L0m01"],
		N["L0m01"],
		N["L0m01"],
		N["L0m00"],
		N["L0m01"],
		N["L0m02"],
		N["_____"],N["_____"],N["_____"],N["_____"],
		N["L0m02"],
		N["L0m02"],
		N["L0m01"],
		N["L0m00"],
		N["L0m01"],
		N["L0m00"],
		N["L0m00"],
		N["L0m00"],
		N["T0m00"],
		N["L0m00"],
		N["L0m01"],
		N["L0m02"],
		N["_____"],N["_____"],N["_____"],
		N["L0m02"],
		N["L0m02"],
		N["L0m01"],
		N["L0m00"],
		N["L0m00"],
		N["T0m00"],
		N["L0m00"],
		N["L0m01"],
		N["L0m00"],
		N["L0m01"],
		N["L0m02"],
		N["_____"],N["_____"],N["_____"],N["_____"],
		N["L0m02"],
		N["L0m01"],
		N["L0m00"],
		N["T0m00"],
		N["L0m00"],
		N["L0m00"],
		N["L0m01"],
		N["L0m01"],
		N["L0m01"],
		N["L0m02"],
		N["L0m02"],
		N["_____"],N["_____"],N["_____"],N["_____"],
		N["L0m02"],
		N["L0m02"],
		N["L0m01"],
		N["L0m00"],
		N["L0m00"],
		N["T0m00"],
		N["L0m00"],
		N["L0m00"],
		N["L0m01"],
		N["L0m01"],
		N["L0m02"],
		N["_____"],N["_____"],N["_____"],N["_____"],
		N["L0m02"],
		N["L0m02"],
		N["L0m01"],
		N["L0m01"],
		N["L0m01"],
		N["L0m00"],
		N["L0m00"],
		N["L0m01"],
		N["L0m00"],
		N["L0m01"],
		N["L0m02"],
		N["_____"],N["_____"],N["_____"],N["_____"],
		N["L0m02"],
		N["L0m01"],
		N["L0m00"],
		N["L0m01"],
		N["L0m01"],
		N["L0m01"],
		N["L0m01"],
		N["L0m01"],
		N["L0m00"],
		N["L0m01"],
		N["L0m02"],
		N["_____"],N["_____"],N["_____"],
		N["L0m02"],
		N["L0m01"],
		N["L0m00"],
		N["T0m00"],
		N["L0m00"],
		N["L0m01"],
		N["L0m00"],
		N["L0m00"],
		N["L0m01"],
		N["L0m01"],
		N["L0m01"],
		N["L0m02"],
		N["_____"],N["_____"],N["_____"],N["_____"],
		N["L0m02"],
		N["L0m01"],
		N["L0m00"],
		N["L0m01"],
		N["L0m00"],
		N["T0m00"],
		N["L0m00"],
		N["L0m01"],
		N["L0m02"],
		N["L0m02"],
		N["L0m02"],
		N["_____"],N["_____"],N["_____"],N["_____"],
		N["L0m02"],
		N["L0m02"],
		N["L0m01"],
		N["L0m01"],
		N["L0m00"],
		N["T0m00"],
		N["L0m00"],
		N["L0m01"],
		N["L0m01"],
		N["L0m02"],
		N["_____"],N["_____"],N["_____"],N["_____"],N["_____"],N["_____"],N["_____"],
		N["L0m02"],
		N["L0m02"],
		N["L0m01"],
		N["L0m00"],
		N["L0m00"],
		N["L0m00"],
		N["L0m01"],
		N["L0m02"],
		N["_____"],N["_____"],N["_____"],N["_____"],N["_____"],N["_____"],N["_____"],N["_____"],
		N["L0m02"],
		N["L0m01"],
		N["L0m01"],
		N["L0m01"],
		N["L0m01"],
		N["L0m01"],
		N["L0m02"],
		N["_____"],N["_____"],N["_____"],N["_____"],N["_____"],N["_____"],N["_____"],N["_____"],
		N["L0m02"],
		N["L0m02"],
		N["L0m02"],
		N["L0m02"],
		N["L0m02"],
		N["L0m02"],
		N["L0m02"],
		N["_____"],N["_____"],N["_____"],N["_____"],N["_____"],N["_____"],N["_____"],N["_____"],N["_____"],N["_____"],N["_____"],N["_____"],N["_____"],N["_____"],N["_____"],N["_____"],N["_____"],N["_____"],N["_____"],N["_____"],N["_____"],N["_____"],N["_____"],N["_____"],N["_____"],N["_____"],N["_____"],N["_____"],N["_____"],N["_____"],N["_____"],N["_____"],N["_____"],N["_____"],N["_____"],N["_____"],N["_____"],N["_____"],N["_____"],N["_____"],N["_____"],N["_____"],N["_____"],N["_____"],N["_____"],N["_____"],N["_____"],N["_____"],N["_____"],N["_____"],N["_____"],N["_____"],N["_____"],N["_____"],N["_____"],
		N["T0m00"],
		N["_____"],N["_____"],N["_____"],N["_____"],N["_____"],N["_____"],N["_____"],N["_____"],N["_____"],N["_____"],N["_____"],N["_____"],N["_____"],N["_____"],
		N["T0m00"],
		N["_____"],N["_____"],N["_____"],N["_____"],N["_____"],N["_____"],N["_____"],N["_____"],N["_____"],N["_____"],N["_____"],N["_____"],N["_____"],N["_____"],
		N["T0m00"],
		N["_____"],N["_____"],N["_____"],N["_____"],N["_____"],N["_____"],N["_____"],N["_____"],N["_____"],N["_____"],N["_____"],N["_____"],N["_____"],N["_____"],
		N["T0m00"],
		N["_____"],N["_____"],N["_____"],N["_____"],N["_____"],N["_____"],N["_____"],N["_____"],N["_____"],N["_____"],N["_____"],N["_____"],N["_____"],N["_____"],
		N["T0m00"],
		N["_____"],N["_____"],N["_____"],N["_____"],N["_____"],N["_____"],N["_____"],N["_____"],N["_____"],N["_____"],N["_____"],N["_____"],N["_____"],N["_____"],
		N["T0m00"],
		N["_____"],N["_____"],N["_____"],N["_____"],N["_____"],N["_____"],N["_____"],N["_____"],N["_____"],N["_____"],N["_____"],N["_____"],N["_____"],N["_____"],
		N["T0m00"],
		N["_____"],N["_____"],N["_____"],N["_____"],N["_____"],N["_____"],N["_____"],N["_____"],N["_____"],N["_____"],N["_____"],N["_____"],N["_____"],N["_____"],
		N["T0m00"],
		N["_____"],N["_____"],N["_____"],N["_____"],N["_____"],N["_____"],N["_____"],N["_____"],N["_____"],N["_____"],N["_____"],N["_____"],N["_____"],N["_____"],
		N["T0m00"],
		N["_____"],N["_____"],N["_____"],N["_____"],N["_____"],N["_____"],N["_____"],N["_____"],N["_____"],N["_____"],N["_____"],N["_____"],N["_____"],N["_____"],
		N["T0m00"],
		N["_____"],N["_____"],N["_____"],N["_____"],N["_____"],N["_____"],N["_____"],N["_____"],N["_____"],N["_____"],N["_____"],N["_____"],N["_____"],
		N["L0m02"],
		N["T0m00"],
		N["_____"],N["_____"],N["_____"],N["_____"],N["_____"],N["_____"],N["_____"],N["_____"],N["_____"],N["_____"],N["_____"],
		N["L0m02"],
		N["L0m02"],
		N["L0m01"],
		N["T0m00"],
		N["L0m02"],
		N["_____"],N["_____"],N["_____"],N["_____"],N["_____"],N["_____"],N["_____"],N["_____"],N["_____"],
		N["L0m02"],
		N["L0m02"],
		N["L0m01"],
		N["L0m00"],
		N["T0m00"],
		N["L0m02"],
		N["L0m02"],
		N["L0m02"],
		N["L0m02"],
		N["_____"],N["_____"],N["_____"],N["_____"],N["_____"],
		N["L0m02"],
		N["L0m02"],
		N["L0m01"],
		N["L0m00"],
		N["T0m00"],
		N["T0m00"],
		N["L0m01"],
		N["L0m01"],
		N["L0m01"],
		N["L0m02"],
		N["_____"],N["_____"],N["_____"],N["_____"],N["_____"],
		N["L0m02"],
		N["L0m01"],
		N["L0m01"],
		N["L0m00"],
		N["T0m00"],
		N["T0m00"],
		N["L0m01"],
		N["L0m00"],
		N["L0m01"],
		N["L0m02"],
		N["L0m02"],
		N["_____"],N["_____"],N["_____"],N["_____"],
		N["L0m02"],
		N["L0m01"],
		N["L0m00"],
		N["L0m00"],
		N["L0m00"],
		N["T0m00"],
		N["L0m00"],
		N["L0m00"],
		N["L0m01"],
		N["L0m01"],
		N["L0m02"],
		N["_____"],N["_____"],N["_____"],N["_____"],
		N["L0m02"],
		N["L0m01"],
		N["L0m00"],
		N["T0m00"],
		N["L0m00"],
		N["T0m00"],
		N["T0m00"],
		N["L0m00"],
		N["L0m00"],
		N["L0m01"],
		N["L0m02"],
		N["_____"],N["_____"],N["_____"],N["_____"],
		N["L0m02"],
		N["L0m01"],
		N["L0m01"],
		N["L0m00"],
		N["L0m01"],
		N["T0m00"],
		N["L0m00"],
		N["L0m01"],
		N["L0m00"],
		N["L0m01"],
		N["L0m02"],
		N["_____"],N["_____"],N["_____"],N["_____"],
		N["L0m02"],
		N["L0m01"],
		N["L0m00"],
		N["L0m00"],
		N["L0m00"],
		N["T0m00"],
		N["L0m00"],
		N["L0m01"],
		N["L0m01"],
		N["L0m01"],
		N["L0m02"],
		N["_____"],N["_____"],N["_____"],N["_____"],
		N["L0m02"],
		N["L0m01"],
		N["L0m00"],
		N["L0m01"],
		N["L0m00"],
		N["T0m00"],
		N["L0m00"],
		N["L0m01"],
		N["L0m00"],
		N["L0m01"],
		N["L0m02"],
		N["_____"],N["_____"],N["_____"],N["_____"],
		N["L0m02"],
		N["L0m01"],
		N["L0m01"],
		N["L0m00"],
		N["L0m00"],
		N["L0m00"],
		N["T0m00"],
		N["L0m00"],
		N["T0m00"],
		N["L0m00"],
		N["L0m01"],
		N["L0m02"],
		N["_____"],N["_____"],N["_____"],
		N["L0m02"],
		N["L0m01"],
		N["L0m01"],
		N["L0m01"],
		N["L0m01"],
		N["L0m00"],
		N["L0m00"],
		N["L0m00"],
		N["T0m00"],
		N["L0m00"],
		N["L0m01"],
		N["L0m02"],
		N["_____"],N["_____"],N["_____"],
		N["L0m02"],
		N["L0m01"],
		N["L0m00"],
		N["L0m01"],
		N["L0m01"],
		N["L0m01"],
		N["L0m01"],
		N["L0m01"],
		N["L0m00"],
		N["L0m01"],
		N["L0m02"],
		N["_____"],N["_____"],N["_____"],N["_____"],
		N["L0m02"],
		N["L0m01"],
		N["L0m01"],
		N["L0m00"],
		N["L0m00"],
		N["L0m00"],
		N["L0m01"],
		N["L0m01"],
		N["L0m01"],
		N["L0m01"],
		N["L0m02"],
		N["_____"],N["_____"],N["_____"],N["_____"],
		N["L0m02"],
		N["L0m02"],
		N["L0m01"],
		N["L0m01"],
		N["L0m01"],
		N["L0m00"],
		N["L0m00"],
		N["L0m00"],
		N["L0m01"],
		N["L0m02"],
		N["L0m02"],
		N["_____"],N["_____"],N["_____"],N["_____"],N["_____"],
		N["L0m02"],
		N["L0m02"],
		N["L0m02"],
		N["L0m01"],
		N["L0m00"],
		N["T0m00"],
		N["T0m00"],
		N["L0m00"],
		N["L0m01"],
		N["L0m02"],
		N["_____"],N["_____"],N["_____"],N["_____"],N["_____"],N["_____"],N["_____"],
		N["L0m02"],
		N["L0m02"],
		N["L0m01"],
		N["L0m00"],
		N["L0m00"],
		N["L0m01"],
		N["L0m02"],
		N["_____"],N["_____"],N["_____"],N["_____"],N["_____"],N["_____"],N["_____"],N["_____"],N["_____"],
		N["L0m02"],
		N["L0m02"],
		N["L0m01"],
		N["L0m01"],
		N["L0m02"],
		N["L0m02"],
		N["_____"],N["_____"],N["_____"],N["_____"],N["_____"],N["_____"],N["_____"],N["_____"],N["_____"],N["_____"],N["_____"],
		N["L0m02"],
		N["L0m02"],
		N["_____"],N["_____"],N["_____"],N["_____"],N["_____"],N["_____"],N["_____"],N["_____"],N["_____"],N["_____"],N["_____"],N["_____"],N["_____"],N["_____"],N["_____"],N["_____"],N["_____"],N["_____"],N["_____"],N["_____"],N["_____"],N["_____"],N["_____"],N["_____"],N["_____"],N["_____"],N["_____"],N["_____"],N["_____"],N["_____"],N["_____"],N["_____"],N["_____"],N["_____"],N["_____"],N["_____"],N["_____"],N["_____"],N["_____"],N["_____"],N["_____"],N["_____"],N["_____"],N["_____"],N["_____"],N["_____"],N["_____"],N["_____"],N["_____"],N["_____"],N["_____"],N["_____"],N["_____"],N["_____"],N["_____"],N["_____"],N["_____"],N["_____"],N["_____"],N["_____"],N["_____"],N["_____"],N["_____"],N["_____"],N["_____"],N["_____"],N["_____"],N["_____"],N["_____"],N["_____"],N["_____"],N["_____"],N["_____"],N["_____"],N["_____"],N["_____"],N["_____"],N["_____"],N["_____"],N["_____"],N["_____"],N["_____"],N["_____"],N["_____"],N["_____"],N["_____"],N["_____"],N["_____"],N["_____"],N["_____"],N["_____"],N["_____"],N["_____"],N["_____"],N["_____"],N["_____"],N["_____"],N["_____"],N["_____"],N["_____"],N["_____"],N["_____"],N["_____"],N["_____"],N["_____"],N["_____"],N["_____"],N["_____"],N["_____"],N["_____"],N["_____"],N["_____"],N["_____"],N["_____"],N["_____"],N["_____"],N["_____"],N["_____"],N["_____"],N["_____"],N["_____"],N["_____"],N["_____"],N["_____"],N["_____"],N["_____"],N["_____"],N["_____"],N["_____"],N["_____"],N["_____"],N["_____"],N["_____"],N["_____"],N["_____"],N["_____"],N["_____"],N["_____"],N["_____"],N["_____"],N["_____"],N["_____"],N["_____"],N["_____"],N["_____"],N["_____"],N["_____"],N["_____"],N["_____"],N["_____"],N["_____"],N["_____"],N["_____"],N["_____"],N["_____"],N["_____"],N["_____"],N["_____"],N["_____"],N["_____"],N["_____"],N["_____"],N["_____"],N["_____"],N["_____"],N["_____"],N["_____"],N["_____"],N["_____"],N["_____"],N["_____"],N["_____"],N["_____"],N["_____"],N["_____"],N["_____"],N["_____"],N["_____"],N["_____"],N["_____"],N["_____"],N["_____"],N["_____"],N["_____"],N["_____"],N["_____"],N["_____"],N["_____"],N["_____"],N["_____"],N["_____"],N["_____"],N["_____"],N["_____"],N["_____"],N["_____"],N["_____"],N["_____"],N["_____"],N["_____"],N["_____"],N["_____"],N["_____"],N["_____"],
		N["L0m02"],
		N["L0m02"],
		N["L0m02"],
		N["L0m02"],
		N["L0m02"],
		N["L0m02"],
		N["_____"],N["_____"],N["_____"],N["_____"],N["_____"],N["_____"],N["_____"],N["_____"],
		N["L0m02"],
		N["L0m02"],
		N["L0m01"],
		N["L0m01"],
		N["L0m01"],
		N["L0m02"],
		N["L0m01"],
		N["L0m02"],
		N["L0m02"],
		N["_____"],N["_____"],N["_____"],N["_____"],N["_____"],
		N["L0m02"],
		N["L0m02"],
		N["L0m01"],
		N["L0m00"],
		N["L0m00"],
		N["L0m01"],
		N["L0m01"],
		N["L0m00"],
		N["L0m01"],
		N["L0m02"],
		N["_____"],N["_____"],N["_____"],N["_____"],N["_____"],
		N["L0m02"],
		N["L0m01"],
		N["L0m00"],
		N["T0m00"],
		N["L0m00"],
		N["L0m01"],
		N["L0m00"],
		N["T0m00"],
		N["L0m00"],
		N["L0m01"],
		N["L0m02"],
		N["_____"],N["_____"],N["_____"],
		N["L0m02"],
		N["L0m01"],
		N["L0m00"],
		N["T0m00"],
		N["L0m00"],
		N["T0m00"],
		N["L0m00"],
		N["T0m00"],
		N["T0m00"],
		N["L0m00"],
		N["L0m01"],
		N["L0m02"],
		N["_____"],N["_____"],N["_____"],N["_____"],
		N["L0m02"],
		N["L0m01"],
		N["L0m00"],
		N["T0m00"],
		N["T0m00"],
		N["L0m00"],
		N["L0m00"],
		N["L0m00"],
		N["T0m00"],
		N["L0m00"],
		N["L0m01"],
		N["L0m02"],
		N["_____"],N["_____"],N["_____"],
		N["L0m02"],
		N["L0m01"],
		N["L0m00"],
		N["L0m00"],
		N["L0m00"],
		N["L0m00"],
		N["L0m00"],
		N["L0m00"],
		N["T0m00"],
		N["L0m00"],
		N["L0m01"],
		N["L0m02"],
		N["_____"],N["_____"],
		N["L0m02"],
		N["L0m01"],
		N["L0m00"],
		N["T0m00"],
		N["L0m00"],
		N["T0m00"],
		N["T0m00"],
		N["T0m00"],
		N["L0m00"],
		N["L0m00"],
		N["L0m01"],
		N["L0m02"],
		N["_____"],N["_____"],N["_____"],
		N["L0m02"],
		N["L0m01"],
		N["L0m00"],
		N["T0m00"],
		N["L0m00"],
		N["T0m00"],
		N["L0m00"],
		N["L0m00"],
		N["L0m01"],
		N["L0m01"],
		N["L0m01"],
		N["L0m02"],
		N["_____"],N["_____"],N["_____"],N["_____"],
		N["L0m02"],
		N["L0m01"],
		N["L0m00"],
		N["T0m00"],
		N["T0m00"],
		N["L0m00"],
		N["L0m00"],
		N["L0m01"],
		N["L0m00"],
		N["L0m01"],
		N["L0m02"],
		N["_____"],N["_____"],N["_____"],N["_____"],
		N["L0m02"],
		N["L0m02"],
		N["L0m01"],
		N["L0m00"],
		N["L0m00"],
		N["T0m00"],
		N["T0m00"],
		N["L0m00"],
		N["T0m00"],
		N["L0m00"],
		N["L0m01"],
		N["L0m02"],
		N["_____"],N["_____"],N["_____"],
		N["L0m02"],
		N["L0m02"],
		N["L0m01"],
		N["L0m00"],
		N["L0m00"],
		N["L0m00"],
		N["L0m00"],
		N["L0m00"],
		N["T0m00"],
		N["L0m00"],
		N["L0m01"],
		N["L0m02"],
		N["_____"],N["_____"],N["_____"],
		N["L0m02"],
		N["L0m01"],
		N["L0m00"],
		N["T0m00"],
		N["T0m00"],
		N["L0m00"],
		N["L0m00"],
		N["L0m01"],
		N["L0m00"],
		N["L0m01"],
		N["L0m02"],
		N["_____"],N["_____"],N["_____"],N["_____"],N["_____"],
		N["L0m02"],
		N["L0m01"],
		N["L0m00"],
		N["L0m00"],
		N["L0m00"],
		N["T0m00"],
		N["L0m00"],
		N["L0m01"],
		N["L0m02"],
		N["L0m02"],
		N["_____"],N["_____"],N["_____"],N["_____"],N["_____"],
		N["L0m02"],
		N["L0m02"],
		N["L0m01"],
		N["L0m01"],
		N["L0m00"],
		N["L0m00"],
		N["L0m00"],
		N["L0m01"],
		N["L0m02"],
		N["_____"],N["_____"],N["_____"],N["_____"],N["_____"],N["_____"],N["_____"],N["_____"],
		N["L0m02"],
		N["L0m01"],
		N["L0m01"],
		N["L0m01"],
		N["L0m01"],
		N["L0m01"],
		N["L0m02"],
		N["_____"],N["_____"],N["_____"],N["_____"],N["_____"],N["_____"],N["_____"],N["_____"],
		N["L0m02"],
		N["L0m02"],
		N["L0m02"],
		N["L0m02"],
		N["L0m02"],
		N["L0m02"],
		N["L0m02"],
		N["_____"],N["_____"],N["_____"],N["_____"],N["_____"],N["_____"],N["_____"],N["_____"],N["_____"],N["_____"],N["_____"],N["_____"],N["_____"],N["_____"],N["_____"],N["_____"],N["_____"],N["_____"],N["_____"],N["_____"],N["_____"],N["_____"],N["_____"],N["_____"],N["_____"],N["_____"],N["_____"],N["_____"],N["_____"],N["_____"],N["_____"],N["_____"],N["_____"],N["_____"],N["_____"],N["_____"],N["_____"],N["_____"],N["_____"],N["_____"],N["_____"],N["_____"],N["_____"],N["_____"],N["_____"],N["_____"],N["_____"],N["_____"],N["_____"],N["_____"],N["_____"],N["_____"],N["_____"],N["_____"],N["_____"],N["_____"],N["_____"],N["_____"],N["_____"],N["_____"],N["_____"],N["_____"],N["_____"],N["_____"],N["_____"],N["_____"],N["_____"],N["_____"],N["_____"],N["_____"],N["_____"],N["_____"],N["_____"],N["_____"],N["_____"],N["_____"],N["_____"],N["_____"],N["_____"],N["_____"],N["_____"],N["_____"],N["_____"],N["_____"],N["_____"],N["_____"],N["_____"],N["_____"],N["_____"],N["_____"],N["_____"],N["_____"],N["_____"],N["_____"],N["_____"],N["_____"],N["_____"],N["_____"],N["_____"],N["_____"],N["_____"],N["_____"],N["_____"],N["_____"],N["_____"],N["_____"],N["_____"],N["_____"],N["_____"],N["_____"],N["_____"],N["_____"],N["_____"],N["_____"],N["_____"],N["_____"],N["_____"],N["_____"],N["_____"],N["_____"],N["_____"],N["_____"],N["_____"],N["_____"],N["_____"],N["_____"],N["_____"],N["_____"],N["_____"],N["_____"],N["_____"],N["_____"],N["_____"],N["_____"],N["_____"],N["_____"],N["_____"],N["_____"],N["_____"],N["_____"],N["_____"],N["_____"],N["_____"],N["_____"],N["_____"],N["_____"],N["_____"],N["_____"],N["_____"],N["_____"],N["_____"],N["_____"],N["_____"],N["_____"],N["_____"],N["_____"],N["_____"],N["_____"],N["_____"],N["_____"],N["_____"],N["_____"],N["_____"],N["_____"],N["_____"],N["_____"],N["_____"],N["_____"],N["_____"],N["_____"],N["_____"],N["_____"],N["_____"],N["_____"],N["_____"],N["_____"],N["_____"],N["_____"],N["_____"],N["_____"],N["_____"],N["_____"],N["_____"],N["_____"],N["_____"],N["_____"],N["_____"],N["_____"],N["_____"],N["_____"],N["_____"],N["_____"],N["_____"],N["_____"],N["_____"],N["_____"],N["_____"],N["_____"],N["_____"],N["_____"],N["_____"],N["_____"],N["_____"],N["_____"],N["_____"],N["_____"],N["_____"],N["_____"],N["_____"],N["_____"],N["_____"],N["_____"],N["_____"],N["_____"],N["_____"],N["_____"],N["_____"],N["_____"],
		N["L0m02"],
		N["L0m02"],
		N["L0m02"],
		N["_____"],N["_____"],N["_____"],N["_____"],N["_____"],N["_____"],N["_____"],N["_____"],N["_____"],N["_____"],
		N["L0m02"],
		N["L0m02"],
		N["L0m02"],
		N["L0m01"],
		N["L0m02"],
		N["L0m02"],
		N["L0m02"],
		N["L0m02"],
		N["L0m02"],
		N["_____"],N["_____"],N["_____"],N["_____"],N["_____"],
		N["L0m02"],
		N["L0m02"],
		N["L0m01"],
		N["L0m01"],
		N["L0m00"],
		N["L0m01"],
		N["L0m01"],
		N["L0m01"],
		N["L0m01"],
		N["L0m02"],
		N["_____"],N["_____"],N["_____"],N["_____"],N["_____"],
		N["L0m02"],
		N["L0m01"],
		N["L0m01"],
		N["L0m00"],
		N["T0m00"],
		N["L0m00"],
		N["L0m01"],
		N["L0m00"],
		N["L0m01"],
		N["L0m02"],
		N["L0m02"],
		N["_____"],N["_____"],N["_____"],N["_____"],
		N["L0m02"],
		N["L0m01"],
		N["L0m00"],
		N["L0m01"],
		N["L0m00"],
		N["L0m01"],
		N["L0m00"],
		N["T0m00"],
		N["L0m00"],
		N["L0m01"],
		N["L0m02"],
		N["_____"],N["_____"],N["_____"],N["_____"],
		N["L0m02"],
		N["L0m01"],
		N["L0m01"],
		N["L0m00"],
		N["L0m00"],
		N["L0m01"],
		N["L0m00"],
		N["L0m00"],
		N["L0m00"],
		N["L0m01"],
		N["L0m02"],
		N["_____"],N["_____"],N["_____"],N["_____"],
		N["L0m02"],
		N["L0m01"],
		N["L0m01"],
		N["L0m01"],
		N["L0m01"],
		N["L0m00"],
		N["T0m00"],
		N["L0m00"],
		N["T0m00"],
		N["L0m00"],
		N["L0m01"],
		N["L0m02"],
		N["_____"],N["_____"],N["_____"],
		N["L0m02"],
		N["L0m01"],
		N["L0m00"],
		N["L0m01"],
		N["L0m00"],
		N["L0m00"],
		N["L0m00"],
		N["L0m00"],
		N["L0m00"],
		N["L0m01"],
		N["L0m02"],
		N["_____"],N["_____"],N["_____"],N["_____"],
		N["L0m02"],
		N["L0m01"],
		N["L0m00"],
		N["L0m00"],
		N["L0m00"],
		N["L0m00"],
		N["L0m01"],
		N["L0m01"],
		N["L0m00"],
		N["L0m01"],
		N["L0m02"],
		N["_____"],N["_____"],N["_____"],N["_____"],
		N["L0m02"],
		N["L0m01"],
		N["L0m01"],
		N["L0m00"],
		N["L0m00"],
		N["T0m00"],
		N["L0m00"],
		N["L0m00"],
		N["T0m00"],
		N["L0m00"],
		N["L0m01"],
		N["L0m02"],
		N["_____"],N["_____"],N["_____"],
		N["L0m02"],
		N["L0m02"],
		N["L0m01"],
		N["L0m01"],
		N["L0m01"],
		N["L0m00"],
		N["L0m00"],
		N["L0m01"],
		N["L0m00"],
		N["L0m01"],
		N["L0m02"],
		N["_____"],N["_____"],N["_____"],N["_____"],N["_____"],
		N["L0m02"],
		N["L0m01"],
		N["L0m01"],
		N["L0m01"],
		N["L0m01"],
		N["L0m01"],
		N["L0m00"],
		N["T0m00"],
		N["L0m00"],
		N["L0m01"],
		N["L0m02"],
		N["_____"],N["_____"],N["_____"],N["_____"],
		N["L0m02"],
		N["L0m01"],
		N["L0m00"],
		N["L0m00"],
		N["L0m01"],
		N["L0m01"],
		N["L0m01"],
		N["L0m00"],
		N["L0m01"],
		N["L0m02"],
		N["_____"],N["_____"],N["_____"],N["_____"],N["_____"],
		N["L0m02"],
		N["L0m01"],
		N["L0m01"],
		N["L0m01"],
		N["L0m00"],
		N["L0m00"],
		N["L0m01"],
		N["L0m01"],
		N["L0m02"],
		N["L0m02"],
		N["_____"],N["_____"],N["_____"],N["_____"],N["_____"],
		N["L0m02"],
		N["L0m02"],
		N["L0m01"],
		N["L0m00"],
		N["T0m00"],
		N["L0m00"],
		N["L0m01"],
		N["L0m02"],
		N["L0m02"],
		N["_____"],N["_____"],N["_____"],N["_____"],N["_____"],N["_____"],N["_____"],N["_____"],
		N["L0m02"],
		N["L0m01"],
		N["L0m00"],
		N["L0m01"],
		N["L0m02"],
		N["L0m02"],
		N["L0m02"],
		N["_____"],N["_____"],N["_____"],N["_____"],N["_____"],N["_____"],N["_____"],N["_____"],
		N["L0m02"],
		N["L0m02"],
		N["L0m01"],
		N["L0m02"],
		N["L0m02"],
		N["L0m02"],
		N["_____"],N["_____"],N["_____"],N["_____"],N["_____"],N["_____"],N["_____"],N["_____"],N["_____"],N["_____"],N["_____"],
		N["L0m02"],
		N["_____"],N["_____"],N["_____"],N["_____"],N["_____"],N["_____"],N["_____"],N["_____"],N["_____"],N["_____"],N["_____"],N["_____"],N["_____"],N["_____"],N["_____"],N["_____"],N["_____"],N["_____"],N["_____"],N["_____"],N["_____"],N["_____"],N["_____"],N["_____"],N["_____"],N["_____"],N["_____"],N["_____"],N["_____"],N["_____"],N["_____"],N["_____"],N["_____"],N["_____"],N["_____"],N["_____"],N["_____"],N["_____"],N["_____"],N["_____"],N["_____"],N["_____"],N["_____"],N["_____"],N["_____"],N["_____"],N["_____"],N["_____"],N["_____"],N["_____"],N["_____"],N["_____"],N["_____"],N["_____"],N["_____"],N["_____"],N["_____"],N["_____"],N["_____"],N["_____"],N["_____"],N["_____"],N["_____"],N["_____"],N["_____"],N["_____"],N["_____"],N["_____"],N["_____"],N["_____"],N["_____"],N["_____"],N["_____"],N["_____"],N["_____"],N["_____"],N["_____"],N["_____"],N["_____"],N["_____"],N["_____"],N["_____"],N["_____"],N["_____"],N["_____"],N["_____"],N["_____"],N["_____"],N["_____"],N["_____"],N["_____"],N["_____"],N["_____"],N["_____"],N["_____"],N["_____"],N["_____"],N["_____"],N["_____"],N["_____"],N["_____"],N["_____"],N["_____"],N["_____"],N["_____"],N["_____"],N["_____"],N["_____"],N["_____"],N["_____"],N["_____"],N["_____"],N["_____"],N["_____"],N["_____"],N["_____"],N["_____"],N["_____"],N["_____"],N["_____"],N["_____"],N["_____"],N["_____"],N["_____"],N["_____"],N["_____"],N["_____"],N["_____"],N["_____"],N["_____"],N["_____"],N["_____"],N["_____"],N["_____"],N["_____"],N["_____"],N["_____"],N["_____"],N["_____"],N["_____"],N["_____"],N["_____"],N["_____"],N["_____"],N["_____"],N["_____"],N["_____"],N["_____"],N["_____"],N["_____"],N["_____"],N["_____"],N["_____"],N["_____"],N["_____"],N["_____"],N["_____"],N["_____"],N["_____"],N["_____"],N["_____"],N["_____"],N["_____"],N["_____"],N["_____"],N["_____"],N["_____"],N["_____"],N["_____"],N["_____"],N["_____"],N["_____"],N["_____"],N["_____"],N["_____"],N["_____"],N["_____"],N["_____"],N["_____"],N["_____"],N["_____"],N["_____"],N["_____"],N["_____"],N["_____"],N["_____"],N["_____"],N["_____"],N["_____"],N["_____"],N["_____"],N["_____"],N["_____"],N["_____"],N["_____"],N["_____"],N["_____"],N["_____"],N["_____"],N["_____"],N["_____"],N["_____"],N["_____"],N["_____"],N["_____"],N["_____"],N["_____"],N["_____"],N["_____"],N["_____"],N["_____"],N["_____"],N["_____"],N["_____"],N["_____"],N["_____"],N["_____"],N["_____"],N["_____"],N["_____"],N["_____"],
		N["L0m02"],
		N["L0m02"],
		N["L0m02"],
		N["L0m02"],
		N["L0m02"],
		N["L0m02"],
		N["L0m02"],
		N["_____"],N["_____"],N["_____"],N["_____"],N["_____"],N["_____"],N["_____"],
		N["L0m02"],
		N["L0m02"],
		N["L0m01"],
		N["L0m01"],
		N["L0m01"],
		N["L0m01"],
		N["L0m02"],
		N["L0m02"],
		N["L0m02"],
		N["_____"],N["_____"],N["_____"],N["_____"],N["_____"],
		N["L0m02"],
		N["L0m02"],
		N["L0m02"],
		N["L0m01"],
		N["L0m00"],
		N["L0m01"],
		N["L0m00"],
		N["L0m01"],
		N["L0m01"],
		N["L0m02"],
		N["_____"],N["_____"],N["_____"],N["_____"],N["_____"],
		N["L0m02"],
		N["L0m02"],
		N["L0m01"],
		N["L0m00"],
		N["T0m00"],
		N["L0m00"],
		N["T0m00"],
		N["L0m00"],
		N["L0m01"],
		N["L0m02"],
		N["L0m02"],
		N["_____"],N["_____"],N["_____"],N["_____"],
		N["L0m02"],
		N["L0m02"],
		N["L0m02"],
		N["L0m01"],
		N["L0m00"],
		N["L0m01"],
		N["L0m00"],
		N["L0m01"],
		N["L0m01"],
		N["L0m01"],
		N["L0m02"],
		N["_____"],N["_____"],N["_____"],N["_____"],
		N["L0m02"],
		N["L0m02"],
		N["L0m02"],
		N["L0m01"],
		N["L0m01"],
		N["L0m00"],
		N["L0m00"],
		N["L0m00"],
		N["L0m00"],
		N["L0m01"],
		N["L0m02"],
		N["_____"],N["_____"],N["_____"],N["_____"],
		N["L0m02"],
		N["L0m02"],
		N["L0m01"],
		N["L0m00"],
		N["L0m00"],
		N["T0m00"],
		N["L0m00"],
		N["T0m00"],
		N["L0m00"],
		N["L0m01"],
		N["L0m02"],
		N["_____"],N["_____"],N["_____"],N["_____"],
		N["L0m02"],
		N["L0m01"],
		N["L0m00"],
		N["T0m00"],
		N["L0m00"],
		N["L0m00"],
		N["L0m00"],
		N["L0m00"],
		N["L0m01"],
		N["L0m01"],
		N["L0m02"],
		N["_____"],N["_____"],N["_____"],N["_____"],
		N["L0m02"],
		N["L0m02"],
		N["L0m01"],
		N["L0m00"],
		N["L0m01"],
		N["L0m00"],
		N["T0m00"],
		N["L0m00"],
		N["L0m00"],
		N["L0m01"],
		N["L0m02"],
		N["_____"],N["_____"],N["_____"],N["_____"],N["_____"],
		N["L0m02"],
		N["L0m02"],
		N["L0m01"],
		N["L0m00"],
		N["T0m00"],
		N["L0m00"],
		N["L0m01"],
		N["L0m01"],
		N["L0m01"],
		N["L0m02"],
		N["_____"],N["_____"],N["_____"],N["_____"],N["_____"],
		N["L0m02"],
		N["L0m02"],
		N["L0m01"],
		N["L0m00"],
		N["L0m00"],
		N["L0m01"],
		N["L0m01"],
		N["L0m00"],
		N["L0m01"],
		N["L0m02"],
		N["_____"],N["_____"],N["_____"],N["_____"],N["_____"],
		N["L0m02"],
		N["L0m01"],
		N["L0m00"],
		N["T0m00"],
		N["L0m00"],
		N["L0m01"],
		N["L0m01"],
		N["L0m01"],
		N["L0m01"],
		N["L0m02"],
		N["_____"],N["_____"],N["_____"],N["_____"],N["_____"],
		N["L0m02"],
		N["L0m02"],
		N["L0m01"],
		N["L0m00"],
		N["L0m01"],
		N["L0m01"],
		N["L0m02"],
		N["L0m02"],
		N["L0m02"],
		N["L0m02"],
		N["_____"],N["_____"],N["_____"],N["_____"],N["_____"],N["_____"],
		N["L0m02"],
		N["L0m02"],
		N["L0m01"],
		N["L0m00"],
		N["L0m01"],
		N["L0m02"],
		N["L0m02"],
		N["_____"],N["_____"],N["_____"],N["_____"],N["_____"],N["_____"],N["_____"],N["_____"],N["_____"],
		N["L0m02"],
		N["L0m01"],
		N["L0m01"],
		N["L0m01"],
		N["L0m02"],
		N["_____"],N["_____"],N["_____"],N["_____"],N["_____"],N["_____"],N["_____"],N["_____"],N["_____"],N["_____"],
		N["L0m02"],
		N["L0m02"],
		N["L0m02"],
		N["L0m02"],
		N["L0m02"],
		N["_____"],N["_____"],N["_____"],N["_____"],N["_____"],N["_____"],N["_____"],N["_____"],N["_____"],N["_____"],N["_____"],N["_____"],N["_____"],N["_____"],N["_____"],N["_____"],N["_____"],N["_____"],N["_____"],N["_____"],N["_____"],N["_____"],N["_____"],N["_____"],N["_____"],N["_____"],N["_____"],N["_____"],N["_____"],N["_____"],N["_____"],N["_____"],N["_____"],N["_____"],N["_____"],N["_____"],N["_____"],N["_____"],N["_____"],N["_____"],N["_____"],N["_____"],N["_____"],N["_____"],N["_____"],N["_____"],N["_____"],N["_____"],N["_____"],N["_____"],N["_____"],N["_____"],N["_____"],N["_____"],N["_____"],N["_____"],N["_____"],N["_____"],N["_____"],N["_____"],N["_____"],N["_____"],N["_____"],N["_____"],N["_____"],N["_____"],N["_____"],N["_____"],N["_____"],N["_____"],N["_____"],N["_____"],N["_____"],N["_____"],N["_____"],N["_____"],N["_____"],N["_____"],N["_____"],N["_____"],N["_____"],N["_____"],N["_____"],N["_____"],N["_____"],N["_____"],N["_____"],N["_____"],N["_____"],N["_____"],N["_____"],N["_____"],N["_____"],N["_____"],N["_____"],N["_____"],N["_____"],N["_____"],N["_____"],N["_____"],N["_____"],N["_____"],N["_____"],N["_____"],N["_____"],N["_____"],N["_____"],N["_____"],N["_____"],N["_____"],N["_____"],N["_____"],N["_____"],N["_____"],N["_____"],N["_____"],N["_____"],N["_____"],N["_____"],N["_____"],N["_____"],N["_____"],N["_____"],N["_____"],N["_____"],N["_____"],N["_____"],N["_____"],N["_____"],N["_____"],N["_____"],N["_____"],N["_____"],N["_____"],N["_____"],N["_____"],N["_____"],N["_____"],N["_____"],N["_____"],N["_____"],N["_____"],N["_____"],N["_____"],N["_____"],N["_____"],N["_____"],N["_____"],N["_____"],N["_____"],N["_____"],N["_____"],N["_____"],N["_____"],N["_____"],N["_____"],N["_____"],N["_____"],N["_____"],N["_____"],N["_____"],N["_____"],N["_____"],N["_____"],N["_____"],N["_____"],N["_____"],N["_____"],N["_____"],N["_____"],N["_____"],N["_____"],N["_____"],N["_____"],N["_____"],N["_____"],N["_____"],N["_____"],N["_____"],N["_____"],N["_____"],N["_____"],N["_____"],N["_____"],N["_____"],N["_____"],N["_____"],N["_____"],N["_____"],N["_____"],N["_____"],N["_____"],N["_____"],N["_____"],N["_____"],N["_____"],N["_____"],N["_____"],N["_____"],N["_____"],N["_____"],N["_____"],N["_____"],N["_____"],N["_____"],N["_____"],N["_____"],N["_____"],N["_____"],N["_____"],N["_____"],N["_____"],N["_____"],N["_____"],N["_____"],N["_____"],N["_____"],N["_____"],N["_____"],N["_____"],N["_____"],N["_____"],N["_____"],N["_____"],N["_____"],N["_____"],N["_____"],N["_____"],N["_____"],N["_____"],N["_____"],N["_____"],N["_____"],N["_____"],N["_____"],
		N["L0m02"],
		N["L0m02"],
		N["L0m02"],
		N["_____"],N["_____"],N["_____"],N["_____"],N["_____"],N["_____"],N["_____"],N["_____"],N["_____"],N["_____"],N["_____"],
		N["L0m02"],
		N["L0m02"],
		N["L0m02"],
		N["L0m02"],
		N["L0m02"],
		N["L0m02"],
		N["L0m02"],
		N["_____"],N["_____"],N["_____"],N["_____"],N["_____"],N["_____"],N["_____"],N["_____"],
		N["L0m02"],
		N["L0m01"],
		N["L0m01"],
		N["L0m01"],
		N["L0m01"],
		N["L0m01"],
		N["L0m02"],
		N["L0m02"],
		N["_____"],N["_____"],N["_____"],N["_____"],N["_____"],N["_____"],N["_____"],
		N["L0m02"],
		N["L0m01"],
		N["L0m00"],
		N["L0m01"],
		N["L0m00"],
		N["L0m01"],
		N["L0m02"],
		N["L0m02"],
		N["_____"],N["_____"],N["_____"],N["_____"],N["_____"],N["_____"],N["_____"],
		N["L0m02"],
		N["L0m01"],
		N["L0m01"],
		N["L0m01"],
		N["L0m01"],
		N["L0m01"],
		N["L0m02"],
		N["L0m02"],
		N["L0m02"],
		N["_____"],N["_____"],N["_____"],N["_____"],N["_____"],
		N["L0m02"],
		N["L0m02"],
		N["L0m02"],
		N["L0m01"],
		N["L0m01"],
		N["L0m01"],
		N["L0m01"],
		N["L0m01"],
		N["L0m02"],
		N["L0m02"],
		N["_____"],N["_____"],N["_____"],N["_____"],N["_____"],
		N["L0m02"],
		N["L0m01"],
		N["L0m01"],
		N["L0m01"],
		N["L0m00"],
		N["L0m01"],
		N["L0m00"],
		N["L0m01"],
		N["L0m02"],
		N["L0m02"],
		N["_____"],N["_____"],N["_____"],N["_____"],N["_____"],
		N["L0m02"],
		N["L0m01"],
		N["L0m00"],
		N["L0m01"],
		N["L0m01"],
		N["L0m01"],
		N["L0m01"],
		N["L0m01"],
		N["L0m02"],
		N["L0m02"],
		N["_____"],N["_____"],N["_____"],N["_____"],N["_____"],
		N["L0m02"],
		N["L0m01"],
		N["L0m01"],
		N["L0m01"],
		N["L0m01"],
		N["L0m00"],
		N["L0m01"],
		N["L0m01"],
		N["L0m02"],
		N["L0m02"],
		N["_____"],N["_____"],N["_____"],N["_____"],N["_____"],
		N["L0m02"],
		N["L0m02"],
		N["L0m02"],
		N["L0m01"],
		N["L0m00"],
		N["L0m01"],
		N["L0m01"],
		N["L0m02"],
		N["L0m02"],
		N["L0m02"],
		N["_____"],N["_____"],N["_____"],N["_____"],N["_____"],N["_____"],
		N["L0m02"],
		N["L0m01"],
		N["L0m01"],
		N["L0m01"],
		N["L0m01"],
		N["L0m02"],
		N["L0m01"],
		N["L0m02"],
		N["L0m02"],
		N["_____"],N["_____"],N["_____"],N["_____"],N["_____"],N["_____"],
		N["L0m02"],
		N["L0m01"],
		N["L0m00"],
		N["L0m01"],
		N["L0m02"],
		N["L0m02"],
		N["L0m02"],
		N["L0m02"],
		N["L0m02"],
		N["_____"],N["_____"],N["_____"],N["_____"],N["_____"],N["_____"],
		N["L0m02"],
		N["L0m01"],
		N["L0m01"],
		N["L0m01"],
		N["L0m02"],
		N["L0m02"],
		N["L0m02"],
		N["L0m02"],
		N["_____"],N["_____"],N["_____"],N["_____"],N["_____"],N["_____"],N["_____"],
		N["L0m02"],
		N["L0m02"],
		N["L0m02"],
		N["L0m01"],
		N["L0m02"],
		N["L0m02"],
		N["_____"],N["_____"],N["_____"],N["_____"],N["_____"],N["_____"],N["_____"],N["_____"],N["_____"],N["_____"],
		N["L0m02"],
		N["L0m02"],
		N["L0m02"],
		N["L0m02"],
		N["L0m02"],
		N["_____"],N["_____"],N["_____"],N["_____"],N["_____"],N["_____"],N["_____"],N["_____"],N["_____"],N["_____"],N["_____"],
		N["L0m02"],
		N["L0m02"],
		N["L0m02"],
		N["_____"],N["_____"],N["_____"],N["_____"],N["_____"],N["_____"],N["_____"],N["_____"],N["_____"],N["_____"],N["_____"],N["_____"],N["_____"],N["_____"],N["_____"],N["_____"],N["_____"],N["_____"],N["_____"],N["_____"],N["_____"],N["_____"],N["_____"],N["_____"],N["_____"],N["_____"],N["_____"],N["_____"],N["_____"],N["_____"],N["_____"],N["_____"],N["_____"],N["_____"],N["_____"],N["_____"],N["_____"],N["_____"],N["_____"],N["_____"],N["_____"],N["_____"],N["_____"],N["_____"],N["_____"],N["_____"],N["_____"],N["_____"],N["_____"],N["_____"],N["_____"],N["_____"],N["_____"],N["_____"],N["_____"],N["_____"],N["_____"],N["_____"],N["_____"],N["_____"],N["_____"],N["_____"],N["_____"],N["_____"],N["_____"],N["_____"],N["_____"],N["_____"],N["_____"],N["_____"],N["_____"],N["_____"],N["_____"],N["_____"],N["_____"],N["_____"],N["_____"],N["_____"],N["_____"],N["_____"],N["_____"],N["_____"],N["_____"],N["_____"],N["_____"],N["_____"],N["_____"],N["_____"],N["_____"],N["_____"],N["_____"],N["_____"],N["_____"],N["_____"],N["_____"],N["_____"],N["_____"],N["_____"],N["_____"],N["_____"],N["_____"],N["_____"],N["_____"],N["_____"],N["_____"],N["_____"],N["_____"],N["_____"],N["_____"],N["_____"],N["_____"],N["_____"],N["_____"],N["_____"],N["_____"],N["_____"],N["_____"],N["_____"],N["_____"],N["_____"],N["_____"],N["_____"],N["_____"],N["_____"],N["_____"],N["_____"],N["_____"],N["_____"],N["_____"],N["_____"],N["_____"],N["_____"],N["_____"],N["_____"],N["_____"],N["_____"],N["_____"],N["_____"],N["_____"],N["_____"],N["_____"],N["_____"],N["_____"],N["_____"],N["_____"],N["_____"],N["_____"],N["_____"],N["_____"],N["_____"],N["_____"],N["_____"],N["_____"],N["_____"],N["_____"],N["_____"],N["_____"],N["_____"],N["_____"],N["_____"],N["_____"],N["_____"],N["_____"],N["_____"],N["_____"],N["_____"],N["_____"],N["_____"],N["_____"],N["_____"],N["_____"],N["_____"],N["_____"],N["_____"],N["_____"],N["_____"],N["_____"],N["_____"],N["_____"],N["_____"],N["_____"],N["_____"],N["_____"],N["_____"],N["_____"],N["_____"],N["_____"],N["_____"],N["_____"],N["_____"],N["_____"],N["_____"],N["_____"],N["_____"],N["_____"],N["_____"],N["_____"],N["_____"],N["_____"],N["_____"],N["_____"],N["_____"],N["_____"],N["_____"],N["_____"],N["_____"],N["_____"],N["_____"],N["_____"],N["_____"],N["_____"],N["_____"],N["_____"],N["_____"],N["_____"],N["_____"],N["_____"],N["_____"],N["_____"],N["_____"],N["_____"],N["_____"],N["_____"],N["_____"],N["_____"],N["_____"],N["_____"],N["_____"],N["_____"],N["_____"],N["_____"],N["_____"],N["_____"],N["_____"],N["_____"],N["_____"],N["_____"],N["_____"],N["_____"],N["_____"],N["_____"],N["_____"],N["_____"],N["_____"],N["_____"],N["_____"],N["_____"],N["_____"],N["_____"],N["_____"],N["_____"],
		N["L0m02"],
		N["L0m02"],
		N["L0m02"],
		N["L0m02"],
		N["L0m02"],
		N["_____"],N["_____"],N["_____"],N["_____"],N["_____"],N["_____"],N["_____"],N["_____"],N["_____"],
		N["L0m02"],
		N["L0m02"],
		N["L0m02"],
		N["L0m02"],
		N["L0m02"],
		N["L0m02"],
		N["L0m02"],
		N["_____"],N["_____"],N["_____"],N["_____"],N["_____"],N["_____"],N["_____"],N["_____"],
		N["L0m02"],
		N["L0m02"],
		N["L0m01"],
		N["L0m02"],
		N["L0m01"],
		N["L0m02"],
		N["L0m02"],
		N["_____"],N["_____"],N["_____"],N["_____"],N["_____"],N["_____"],N["_____"],N["_____"],
		N["L0m02"],
		N["L0m02"],
		N["L0m02"],
		N["L0m02"],
		N["L0m02"],
		N["L0m02"],
		N["L0m02"],
		N["_____"],N["_____"],N["_____"],N["_____"],N["_____"],N["_____"],N["_____"],N["_____"],
		N["L0m02"],
		N["L0m02"],
		N["L0m02"],
		N["L0m02"],
		N["L0m02"],
		N["L0m02"],
		N["L0m02"],
		N["L0m02"],
		N["_____"],N["_____"],N["_____"],N["_____"],N["_____"],N["_____"],
		N["L0m02"],
		N["L0m02"],
		N["L0m02"],
		N["L0m02"],
		N["L0m01"],
		N["L0m02"],
		N["L0m01"],
		N["L0m02"],
		N["L0m02"],
		N["_____"],N["_____"],N["_____"],N["_____"],N["_____"],N["_____"],
		N["L0m02"],
		N["L0m02"],
		N["L0m01"],
		N["L0m02"],
		N["L0m02"],
		N["L0m02"],
		N["L0m02"],
		N["L0m02"],
		N["L0m02"],
		N["_____"],N["_____"],N["_____"],N["_____"],N["_____"],N["_____"],
		N["L0m02"],
		N["L0m02"],
		N["L0m02"],
		N["L0m02"],
		N["L0m02"],
		N["L0m01"],
		N["L0m02"],
		N["L0m02"],
		N["_____"],N["_____"],N["_____"],N["_____"],N["_____"],N["_____"],N["_____"],N["_____"],
		N["L0m02"],
		N["L0m02"],
		N["L0m02"],
		N["L0m01"],
		N["L0m02"],
		N["L0m02"],
		N["L0m02"],
		N["_____"],N["_____"],N["_____"],N["_____"],N["_____"],N["_____"],N["_____"],N["_____"],
		N["L0m02"],
		N["L0m02"],
		N["L0m02"],
		N["L0m02"],
		N["L0m02"],
		N["L0m02"],
		N["L0m02"],
		N["_____"],N["_____"],N["_____"],N["_____"],N["_____"],N["_____"],N["_____"],N["_____"],
		N["L0m02"],
		N["L0m02"],
		N["L0m01"],
		N["L0m02"],
		N["L0m02"],
		N["_____"],N["_____"],N["_____"],N["_____"],N["_____"],N["_____"],N["_____"],N["_____"],N["_____"],N["_____"],
		N["L0m02"],
		N["L0m02"],
		N["L0m02"],
		N["L0m02"],
		N["L0m02"],
		N["_____"],N["_____"],N["_____"],N["_____"],N["_____"],N["_____"],N["_____"],N["_____"],N["_____"],N["_____"],N["_____"],
		N["L0m02"],
		N["L0m02"],
		N["L0m02"],
		N["_____"],N["_____"],N["_____"],N["_____"],N["_____"],N["_____"],N["_____"],N["_____"],N["_____"],N["_____"],N["_____"],N["_____"],N["_____"],N["_____"],N["_____"],N["_____"],N["_____"],N["_____"],N["_____"],N["_____"],N["_____"],N["_____"],N["_____"],N["_____"],N["_____"],N["_____"],N["_____"],N["_____"],N["_____"],N["_____"],N["_____"],N["_____"],N["_____"],N["_____"],N["_____"],N["_____"],N["_____"],N["_____"],N["_____"],N["_____"],N["_____"],N["_____"],N["_____"],N["_____"],N["_____"],N["_____"],N["_____"],N["_____"],N["_____"],N["_____"],N["_____"],N["_____"],N["_____"],N["_____"],N["_____"],N["_____"],N["_____"],N["_____"],N["_____"],N["_____"],N["_____"],N["_____"],N["_____"],N["_____"],N["_____"],N["_____"],N["_____"],N["_____"],N["_____"],N["_____"],N["_____"],N["_____"],N["_____"],N["_____"],N["_____"],N["_____"],N["_____"],N["_____"],N["_____"],N["_____"],N["_____"],N["_____"],N["_____"],N["_____"],N["_____"],N["_____"],N["_____"],N["_____"],N["_____"],N["_____"],N["_____"],N["_____"],N["_____"],N["_____"],N["_____"],N["_____"],N["_____"],N["_____"],N["_____"],N["_____"],N["_____"],N["_____"],N["_____"],N["_____"],N["_____"],N["_____"],N["_____"],N["_____"],N["_____"],N["_____"],N["_____"],N["_____"],N["_____"],N["_____"],N["_____"],N["_____"],N["_____"],N["_____"],N["_____"],N["_____"],N["_____"],N["_____"],N["_____"],N["_____"],N["_____"],N["_____"],N["_____"],N["_____"],N["_____"],N["_____"],N["_____"],N["_____"],N["_____"],N["_____"],N["_____"],N["_____"],N["_____"],N["_____"],N["_____"],N["_____"],N["_____"],N["_____"],N["_____"],N["_____"],N["_____"],N["_____"],N["_____"],N["_____"],N["_____"],N["_____"],N["_____"],N["_____"],N["_____"],N["_____"],N["_____"],N["_____"],N["_____"],N["_____"],N["_____"],N["_____"],N["_____"],N["_____"],N["_____"],N["_____"],N["_____"],N["_____"],N["_____"],N["_____"],N["_____"],N["_____"],N["_____"],N["_____"],N["_____"],N["_____"],N["_____"],N["_____"],N["_____"],N["_____"],N["_____"],N["_____"],N["_____"],N["_____"],N["_____"],N["_____"],N["_____"],N["_____"],N["_____"],N["_____"],N["_____"],N["_____"],N["_____"],N["_____"],N["_____"],N["_____"],N["_____"],N["_____"],N["_____"],N["_____"],N["_____"],N["_____"],N["_____"],N["_____"],N["_____"],N["_____"],N["_____"],N["_____"],N["_____"],N["_____"],N["_____"],N["_____"],N["_____"],N["_____"],N["_____"],N["_____"],N["_____"],N["_____"],N["_____"],N["_____"],N["_____"],N["_____"],N["_____"],N["_____"],N["_____"],N["_____"],N["_____"],N["_____"],N["_____"],N["_____"],N["_____"],N["_____"],N["_____"],N["_____"],N["_____"],N["_____"],N["_____"],N["_____"],N["_____"],N["_____"],N["_____"],N["_____"],N["_____"],N["_____"],N["_____"],N["_____"],N["_____"],N["_____"],N["_____"],N["_____"],N["_____"],N["_____"],N["_____"],N["_____"],N["_____"],N["_____"],N["_____"],N["_____"],N["_____"],N["_____"],N["_____"],N["_____"],N["_____"],N["_____"],N["_____"],N["_____"],N["_____"],N["_____"],N["_____"],N["_____"],N["_____"],N["_____"],N["_____"],N["_____"],N["_____"],N["_____"],N["_____"],N["_____"],N["_____"],N["_____"],N["_____"],N["_____"],N["_____"],N["_____"],N["_____"],N["_____"],N["_____"],N["_____"],N["_____"],N["_____"],N["_____"],N["_____"],N["_____"],N["_____"],N["_____"],N["_____"],N["_____"],N["_____"],N["_____"],N["_____"],N["_____"],N["_____"],N["_____"],N["_____"],N["_____"],N["_____"],N["_____"],N["_____"],N["_____"],N["_____"],N["_____"],N["_____"],N["_____"],N["_____"],N["_____"],
		N["L0m02"],
		N["_____"],
		N["L0m02"],
		N["_____"],N["_____"],N["_____"],N["_____"],N["_____"],N["_____"],N["_____"],N["_____"],N["_____"],N["_____"],N["_____"],N["_____"],N["_____"],N["_____"],N["_____"],N["_____"],N["_____"],N["_____"],N["_____"],N["_____"],N["_____"],N["_____"],N["_____"],N["_____"],N["_____"],N["_____"],N["_____"],N["_____"],N["_____"],N["_____"],N["_____"],N["_____"],N["_____"],N["_____"],N["_____"],N["_____"],N["_____"],N["_____"],N["_____"],N["_____"],N["_____"],N["_____"],N["_____"],
		N["L0m02"],
		N["_____"],
		N["L0m02"],
		N["_____"],N["_____"],N["_____"],N["_____"],N["_____"],N["_____"],N["_____"],N["_____"],N["_____"],N["_____"],
		N["L0m02"],
		N["_____"],N["_____"],N["_____"],N["_____"],N["_____"],N["_____"],N["_____"],N["_____"],N["_____"],N["_____"],N["_____"],N["_____"],N["_____"],N["_____"],N["_____"],N["_____"],N["_____"],
		N["L0m02"],
		N["_____"],N["_____"],N["_____"],N["_____"],N["_____"],N["_____"],N["_____"],N["_____"],N["_____"],N["_____"],N["_____"],N["_____"],N["_____"],
		N["L0m02"],
		N["_____"],N["_____"],N["_____"],N["_____"],N["_____"],N["_____"],N["_____"],N["_____"],N["_____"],N["_____"],N["_____"],N["_____"],N["_____"],N["_____"],N["_____"],N["_____"],N["_____"],N["_____"],N["_____"],N["_____"],N["_____"],N["_____"],N["_____"],N["_____"],N["_____"],N["_____"],N["_____"],N["_____"],
		N["L0m02"],
		N["_____"],N["_____"],N["_____"],N["_____"],N["_____"],N["_____"],N["_____"],N["_____"],N["_____"],N["_____"],N["_____"],N["_____"],N["_____"],N["_____"],N["_____"],N["_____"],N["_____"],N["_____"],N["_____"],N["_____"],N["_____"],N["_____"],N["_____"],N["_____"],N["_____"],N["_____"],N["_____"],N["_____"],N["_____"],N["_____"],N["_____"],N["_____"],N["_____"],N["_____"],N["_____"],N["_____"],N["_____"],N["_____"],N["_____"],N["_____"],N["_____"],N["_____"],N["_____"],N["_____"],N["_____"],N["_____"],N["_____"],N["_____"],N["_____"],N["_____"],N["_____"],N["_____"],N["_____"],N["_____"],N["_____"],N["_____"],N["_____"],N["_____"],N["_____"],N["_____"],N["_____"],N["_____"],N["_____"],N["_____"],N["_____"],N["_____"],N["_____"],N["_____"],N["_____"],N["_____"],N["_____"],N["_____"],N["_____"],N["_____"],N["_____"],N["_____"],N["_____"],N["_____"],N["_____"],N["_____"],N["_____"],N["_____"],N["_____"],N["_____"],N["_____"],N["_____"],N["_____"],N["_____"],N["_____"],N["_____"],N["_____"],N["_____"],N["_____"],N["_____"],N["_____"],N["_____"],N["_____"],N["_____"],N["_____"],N["_____"],N["_____"],N["_____"],N["_____"],N["_____"],N["_____"],N["_____"],N["_____"],N["_____"],N["_____"],N["_____"],N["_____"],N["_____"],N["_____"],N["_____"],N["_____"],N["_____"],N["_____"],N["_____"],N["_____"],N["_____"],N["_____"],N["_____"],N["_____"],N["_____"],N["_____"],N["_____"],N["_____"],N["_____"],N["_____"],N["_____"],N["_____"],N["_____"],N["_____"],N["_____"],N["_____"],N["_____"],N["_____"],N["_____"],N["_____"],N["_____"],N["_____"],N["_____"],N["_____"],N["_____"],N["_____"],N["_____"],N["_____"],N["_____"],N["_____"],N["_____"],N["_____"],N["_____"],N["_____"],N["_____"],N["_____"],N["_____"],N["_____"],N["_____"],N["_____"],N["_____"],N["_____"],N["_____"],N["_____"],N["_____"],N["_____"],N["_____"],N["_____"],N["_____"],N["_____"],N["_____"],N["_____"],N["_____"],N["_____"],N["_____"],N["_____"],N["_____"],N["_____"],N["_____"],N["_____"],N["_____"],N["_____"],N["_____"],N["_____"],N["_____"],N["_____"],N["_____"],N["_____"],N["_____"],N["_____"],N["_____"],N["_____"],N["_____"],N["_____"],N["_____"],N["_____"],N["_____"],N["_____"],N["_____"],N["_____"],N["_____"],N["_____"],N["_____"],N["_____"],N["_____"],N["_____"],N["_____"],N["_____"],N["_____"],N["_____"],N["_____"],N["_____"],N["_____"],N["_____"],N["_____"],N["_____"],N["_____"],N["_____"],N["_____"],N["_____"],N["_____"],N["_____"],N["_____"],N["_____"],N["_____"],N["_____"],N["_____"],N["_____"],N["_____"],N["_____"],N["_____"],N["_____"],N["_____"],N["_____"],N["_____"],N["_____"],N["_____"],N["_____"],N["_____"],N["_____"],N["_____"],N["_____"],N["_____"],N["_____"],N["_____"],N["_____"],N["_____"],N["_____"],N["_____"],N["_____"],N["_____"],N["_____"],N["_____"],N["_____"],N["_____"],N["_____"],N["_____"],N["_____"],N["_____"],N["_____"],N["_____"],N["_____"],N["_____"],N["_____"],N["_____"],N["_____"],N["_____"],N["_____"],N["_____"],N["_____"],N["_____"],N["_____"],N["_____"],N["_____"],N["_____"],N["_____"],N["_____"],N["_____"],N["_____"],N["_____"],N["_____"],N["_____"],N["_____"],N["_____"],N["_____"],N["_____"],N["_____"],N["_____"],N["_____"],N["_____"],N["_____"],N["_____"],N["_____"],N["_____"],N["_____"],N["_____"],N["_____"],N["_____"],N["_____"],N["_____"],N["_____"],N["_____"],N["_____"],N["_____"],N["_____"],N["_____"],N["_____"],N["_____"],N["_____"],N["_____"],N["_____"],N["_____"],N["_____"],N["_____"],N["_____"],N["_____"],N["_____"],N["_____"],N["_____"],N["_____"],N["_____"],N["_____"],N["_____"],N["_____"],N["_____"],N["_____"],N["_____"],N["_____"],N["_____"],N["_____"],N["_____"],N["_____"],N["_____"],N["_____"],N["_____"],N["_____"],N["_____"],N["_____"],N["_____"],N["_____"],N["_____"],N["_____"],N["_____"],N["_____"],N["_____"],N["_____"],N["_____"],N["_____"],N["_____"],N["_____"],N["_____"],N["_____"],N["_____"],N["_____"],N["_____"],N["_____"],N["_____"],N["_____"],N["_____"],N["_____"],N["_____"],N["_____"],N["_____"],N["_____"],N["_____"],N["_____"],N["_____"],N["_____"],N["_____"],N["_____"],N["_____"],N["_____"],N["_____"],N["_____"],N["_____"],N["_____"],N["_____"],N["_____"],N["_____"],N["_____"],N["_____"],N["_____"],N["_____"],N["_____"],N["_____"],N["_____"],N["_____"],N["_____"],N["_____"],N["_____"],N["_____"],N["_____"],N["_____"],N["_____"],N["_____"],N["_____"],N["_____"],N["_____"],N["_____"],N["_____"],N["_____"],N["_____"],N["_____"],N["_____"],N["_____"],N["_____"],N["_____"],N["_____"],N["_____"],N["_____"],N["_____"],N["_____"],N["_____"],N["_____"],N["_____"],N["_____"],N["_____"],N["_____"],N["_____"],N["_____"],N["_____"],N["_____"],N["_____"],N["_____"],N["_____"],N["_____"],N["_____"],N["_____"],N["_____"],N["_____"],N["_____"],N["_____"],N["_____"],N["_____"],N["_____"],N["_____"],N["_____"],N["_____"],N["_____"],N["_____"],N["_____"],N["_____"],N["_____"],N["_____"],N["_____"],N["_____"],N["_____"],N["_____"],N["_____"],N["_____"],N["_____"],N["_____"],N["_____"],N["_____"],N["_____"],N["_____"],N["_____"],N["_____"],N["_____"],N["_____"],N["_____"],N["_____"],N["_____"],N["_____"],N["_____"],N["_____"],N["_____"],N["_____"],N["_____"],N["_____"],N["_____"],N["_____"],N["_____"],N["_____"],N["_____"],N["_____"],N["_____"],N["_____"],N["_____"],N["_____"],N["_____"],N["_____"],N["_____"],N["_____"],N["_____"],N["_____"],N["_____"],N["_____"],N["_____"],N["_____"],N["_____"],N["_____"],N["_____"],N["_____"],N["_____"],N["_____"],N["_____"],N["_____"],N["_____"],N["_____"],N["_____"],N["_____"],N["_____"],N["_____"],N["_____"],N["_____"],N["_____"],N["_____"],N["_____"],N["_____"],N["_____"],N["_____"],N["_____"],N["_____"],N["_____"],N["_____"],N["_____"],N["_____"],N["_____"],N["_____"],N["_____"],N["_____"],N["_____"],N["_____"],N["_____"],N["_____"],N["_____"],N["_____"],N["_____"],N["_____"],N["_____"],N["_____"],N["_____"],N["_____"],N["_____"],N["_____"],N["_____"],N["_____"],N["_____"],N["_____"],N["_____"],N["_____"],N["_____"],N["_____"],N["_____"],N["_____"],N["_____"],N["_____"],N["_____"],N["_____"],N["_____"],N["_____"],N["_____"],N["_____"],N["_____"],N["_____"],N["_____"],N["_____"],N["_____"],N["_____"],N["_____"],N["_____"],N["_____"],N["_____"]
	}
}