



--Tree Fern Palm
	local N = gal.N

	local __ = {name = "air",param2 = 0,prob = 0}
	local tr = {name = "gal:tree_fern_palm_trunk", param2 = 0, prob = 254}
	local tt = {name = "gal:tree_fern_palm_trunk_top", param2 = 0, prob = 254}
	local lp = {name = "gal:tree_fern_palm_leaves", param2 = 0, prob = 254}
	local ln = {name = "gal:tree_fern_palm_leaves_end", param2 = 0, prob = 254}
	local le = {name = "gal:tree_fern_palm_leaves_end", param2 = 1, prob = 254}
	local ls = {name = "gal:tree_fern_palm_leaves_end", param2 = 2, prob = 254}
	local lw = {name = "gal:tree_fern_palm_leaves_end", param2 = 3, prob = 254}
	local cr = {name = "gal:tree_fern_palm_crown", param2 = 0, prob = 254}
	
	return {
		size = {x = 7, y = 7, z = 7},
		data = {

			__, __, __, __, __, __, __, 
			__, __, __, __, __, __, __, 
			__, __, __, __, __, __, __, 
			__, __, __, __, __, __, __, 
			__, __, __, ls, __, __, __, 
			__, __, __, lp, __, __, __, 
			__, __, __, __, __, __, __, 

			__, __, __, __, __, __, __, 
			__, __, __, __, __, __, __, 
			__, __, __, __, __, __, __, 
			__, __, __, __, __, __, __, 
			__, __, __, __, __, __, __, 
			__, __, __, __, __, __, __, 
			__, __, __, lp, __, __, __, 

			__, __, __, __, __, __, __, 
			__, __, __, __, __, __, __, 
			__, __, __, __, __, __, __, 
			__, __, __, __, __, __, __, 
			__, __, __, __, __, __, __, 
			__, __, __, lp, __, __, __, 
			__, __, __, __, __, __, __, 

			__, __, __, tr, __, __, __, 
			__, __, __, tr, __, __, __, 
			__, __, __, tr, __, __, __, 
			__, __, __, tr, __, __, __, 
			lw, __, __, tt, __, __, le, 
			lp, __, lp, cr, lp, __, lp, 
			__, lp, __, __, __, lp, __, 

			__, __, __, __, __, __, __, 
			__, __, __, __, __, __, __, 
			__, __, __, __, __, __, __, 
			__, __, __, __, __, __, __, 
			__, __, __, __, __, __, __, 
			__, __, __, lp, __, __, __, 
			__, __, __, __, __, __, __, 

			__, __, __, __, __, __, __, 
			__, __, __, __, __, __, __, 
			__, __, __, __, __, __, __, 
			__, __, __, __, __, __, __, 
			__, __, __, __, __, __, __, 
			__, __, __, __, __, __, __, 
			__, __, __, lp, __, __, __, 

			__, __, __, __, __, __, __, 
			__, __, __, __, __, __, __, 
			__, __, __, __, __, __, __, 
			__, __, __, __, __, __, __, 
			__, __, __, ln, __, __, __, 
			__, __, __, lp, __, __, __, 
			__, __, __, __, __, __, __, 

		},
		yslice_prob = {
			{ypos = 0,prob = 254},
			{ypos = 1,prob = 127},
			{ypos = 2,prob = 254},
			{ypos = 3,prob = 254},
			{ypos = 4,prob = 254},
			{ypos = 5,prob = 254},
			{ypos = 6,prob = 254}
		}
	}
