

--Shoestring Acacia 01 Tree
	local N = gal.N

	
	return {
	yslice_prob = {
		
	},
	size = {x = 5,y = 15,z = 5},
	data = {
		N["_____"],N["_____"],N["_____"],N["_____"],N["_____"],
		N["_____"],N["_____"],N["_____"],N["_____"],N["_____"],
		N["_____"],N["_____"],N["_____"],N["_____"],N["_____"],
		N["_____"],N["_____"],N["_____"],N["_____"],N["_____"],
		N["_____"],N["_____"],N["_____"],N["_____"],N["_____"],
		N["_____"],N["_____"],N["_____"],N["_____"],N["_____"],
		N["_____"],N["_____"],N["_____"],N["_____"],N["_____"],
		N["_____"],N["_____"],N["_____"],N["_____"],N["_____"],
		N["_____"],N["_____"],N["_____"],N["_____"],N["_____"],
		N["_____"],N["_____"],N["L0m01"],N["_____"],N["_____"],
		N["_____"],N["_____"],N["_____"],N["_____"],N["_____"],
		N["_____"],N["_____"],N["_____"],N["_____"],N["_____"],
		N["_____"],N["_____"],N["_____"],N["_____"],N["_____"],
		N["_____"],N["_____"],N["_____"],N["_____"],N["_____"],
		N["_____"],N["_____"],N["_____"],N["_____"],N["_____"],
		N["_____"],N["_____"],N["_____"],N["_____"],N["_____"],
		N["_____"],N["_____"],N["_____"],N["_____"],N["_____"],
		N["_____"],N["_____"],N["_____"],N["_____"],N["_____"],
		N["_____"],N["_____"],N["_____"],N["_____"],N["_____"],
		N["_____"],N["_____"],N["_____"],N["_____"],N["_____"],
		N["_____"],N["_____"],N["_____"],N["_____"],N["_____"],
		N["_____"],N["_____"],N["_____"],N["_____"],N["_____"],
		N["_____"],N["_____"],N["_____"],N["_____"],N["_____"],
		N["_____"],N["L0m01"],N["L0m01"],N["L0m01"],N["_____"],
		N["_____"],N["L0m01"],N["L0m00"],N["L0m01"],N["_____"],
		N["_____"],N["L0m01"],N["L0m01"],N["L0m01"],N["_____"],
		N["_____"],N["_____"],N["_____"],N["_____"],N["_____"],
		N["_____"],N["_____"],N["_____"],N["_____"],N["_____"],
		N["_____"],N["_____"],N["_____"],N["_____"],N["_____"],
		N["_____"],N["_____"],N["_____"],N["_____"],N["_____"],
		N["_____"],N["_____"],N["_____"],N["_____"],N["_____"],
		N["_____"],N["_____"],N["T0m00"],N["_____"],N["_____"],
		N["_____"],N["_____"],N["T0m00"],N["_____"],N["_____"],
		N["_____"],N["_____"],N["T0m00"],N["_____"],N["_____"],
		N["_____"],N["_____"],N["T0m00"],N["_____"],N["_____"],
		N["_____"],N["_____"],N["T0m00"],N["_____"],N["_____"],
		N["_____"],N["_____"],N["T0m00"],N["_____"],N["_____"],
		N["_____"],N["_____"],N["T0m00"],N["_____"],N["_____"],
		N["_____"],N["L0m01"],N["T0m00"],N["L0m01"],N["_____"],
		N["L0m01"],N["L0m00"],N["T0m00"],N["L0m00"],N["L0m01"],
		N["_____"],N["L0m01"],N["L0m00"],N["L0m01"],N["_____"],
		N["_____"],N["_____"],N["L0m01"],N["_____"],N["_____"],
		N["_____"],N["_____"],N["_____"],N["_____"],N["_____"],
		N["_____"],N["_____"],N["_____"],N["_____"],N["_____"],
		N["_____"],N["_____"],N["_____"],N["_____"],N["_____"],
		N["_____"],N["_____"],N["_____"],N["_____"],N["_____"],
		N["_____"],N["_____"],N["_____"],N["_____"],N["_____"],
		N["_____"],N["_____"],N["_____"],N["_____"],N["_____"],
		N["_____"],N["_____"],N["_____"],N["_____"],N["_____"],
		N["_____"],N["_____"],N["_____"],N["_____"],N["_____"],
		N["_____"],N["_____"],N["_____"],N["_____"],N["_____"],
		N["_____"],N["_____"],N["_____"],N["_____"],N["_____"],
		N["_____"],N["_____"],N["_____"],N["_____"],N["_____"],
		N["_____"],N["L0m01"],N["L0m01"],N["L0m01"],N["_____"],
		N["_____"],N["L0m01"],N["L0m00"],N["L0m01"],N["_____"],
		N["_____"],N["L0m01"],N["L0m01"],N["L0m01"],N["_____"],
		N["_____"],N["_____"],N["_____"],N["_____"],N["_____"],
		N["_____"],N["_____"],N["_____"],N["_____"],N["_____"],
		N["_____"],N["_____"],N["_____"],N["_____"],N["_____"],
		N["_____"],N["_____"],N["_____"],N["_____"],N["_____"],
		N["_____"],N["_____"],N["_____"],N["_____"],N["_____"],
		N["_____"],N["_____"],N["_____"],N["_____"],N["_____"],
		N["_____"],N["_____"],N["_____"],N["_____"],N["_____"],
		N["_____"],N["_____"],N["_____"],N["_____"],N["_____"],
		N["_____"],N["_____"],N["_____"],N["_____"],N["_____"],
		N["_____"],N["_____"],N["_____"],N["_____"],N["_____"],
		N["_____"],N["_____"],N["_____"],N["_____"],N["_____"],
		N["_____"],N["_____"],N["_____"],N["_____"],N["_____"],
		N["_____"],N["_____"],N["_____"],N["_____"],N["_____"],
		N["_____"],N["_____"],N["L0m01"],N["_____"],N["_____"],
		N["_____"],N["_____"],N["_____"],N["_____"],N["_____"],
		N["_____"],N["_____"],N["_____"],N["_____"],N["_____"],
		N["_____"],N["_____"],N["_____"],N["_____"],N["_____"],
		N["_____"],N["_____"],N["_____"],N["_____"],N["_____"],
		N["_____"],N["_____"],N["_____"],N["_____"],N["_____"]
	}
}