

--Stilted Mangrove 01 Tree
	local N = gal.N

	
	return {
	yslice_prob = {
		
	},
	size = {
		y = 7,
		x = 5,
		z = 5
	},
	data = {
		N["_____"],N["_____"],N["_____"],N["_____"],N["_____"],N["_____"],N["_____"],N["_____"],N["_____"],N["_____"],N["_____"],N["_____"],N["_____"],N["_____"],N["_____"],N["_____"],N["_____"],N["_____"],N["_____"],N["_____"],
		N["L0m03"],
		N["L0m02"],
		N["L0m01"],
		N["L0m00"],
		N["L0m00"],
		N["_____"],
		N["L0m03"],
		N["L0m02"],
		N["L0m01"],
		N["L0m00"],
		N["L0m00"],
		N["L0m00"],
		N["L0m01"],
		N["L0m02"],
		N["L0m03"],
		N["_____"],N["_____"],N["_____"],N["_____"],N["_____"],N["_____"],N["_____"],
		N["T0m00"],
		N["_____"],N["_____"],N["_____"],N["_____"],
		N["T0m00"],
		N["_____"],N["_____"],N["_____"],N["_____"],N["_____"],N["_____"],N["_____"],
		N["L0m02"],
		N["L0m03"],
		N["L0m02"],
		N["L0m01"],
		N["L0m00"],
		N["L0m03"],
		N["L0m03"],
		N["L0m02"],
		N["L0m01"],
		N["L0m01"],
		N["L0m00"],
		N["L0m01"],
		N["L0m02"],
		N["L0m03"],
		N["L0m02"],
		N["_____"],N["_____"],N["_____"],N["_____"],N["_____"],N["_____"],
		N["T0m00"],
		N["T0m00"],
		N["T0m00"],
		N["_____"],N["_____"],
		N["T0m00"],
		N["T0m00"],
		N["T0m00"],
		N["_____"],N["_____"],N["_____"],
		N["T0m00"],
		N["_____"],N["_____"],
		N["L0m01"],
		N["L0m02"],
		N["T0m00"],
		N["L0m02"],
		N["L0m01"],
		N["L0m02"],
		N["L0m02"],
		N["L0m02"],
		N["L0m02"],
		N["L0m02"],
		N["L0m01"],
		N["L0m02"],
		N["L0m02"],
		N["L0m02"],
		N["L0m01"],
		N["_____"],N["_____"],N["_____"],N["_____"],N["_____"],N["_____"],N["_____"],
		N["T0m00"],
		N["_____"],N["_____"],N["_____"],N["_____"],
		N["T0m00"],
		N["_____"],N["_____"],N["_____"],N["_____"],N["_____"],N["_____"],N["_____"],
		N["L0m00"],
		N["L0m01"],
		N["L0m02"],
		N["L0m03"],
		N["L0m02"],
		N["L0m01"],
		N["L0m01"],
		N["L0m02"],
		N["L0m03"],
		N["L0m03"],
		N["L0m02"],
		N["L0m03"],
		N["L0m02"],
		N["L0m01"],
		N["L0m00"],
		N["_____"],N["_____"],N["_____"],N["_____"],N["_____"],N["_____"],N["_____"],N["_____"],N["_____"],N["_____"],N["_____"],N["_____"],N["_____"],N["_____"],N["_____"],N["_____"],N["_____"],N["_____"],N["_____"],N["_____"],
		N["L0m00"],
		N["L0m00"],
		N["L0m01"],
		N["L0m02"],
		N["L0m03"],
		N["L0m00"],
		N["L0m01"],
		N["L0m02"],
		N["L0m03"],
		N["_____"],
		N["L0m03"],
		N["L0m02"],
		N["L0m01"],
		N["L0m00"],
		N["L0m00"]
	}
}